Workbook

Sheet _Planlagt_drift
A1: Adresse | B1: Anvendelse | C1: Type | D1: Ansvarlig | E1: Post nr. | F1: By | G1: 2024 | H1: 2025 | I1: 2026 | J1: 2027 | K1: 2028 | L1: 2029 | M1: 2030 | N1: 2031 | O1: 2032 | P1: 2033 | Q1: 2034 | R1: 2035 | S1: 2036 | T1: 2037 | U1: 2038 | V1: 2039 | W1: 2040 | X1: 2041 | Y1: 2042 | Z1: Total
A2: Adelgade 1 | B2: Off. Toilet | C2: Øvrige - Konto 13 | D2: Allan Kvistgaard Laursen | E2: 5600 | F2: Faaborg | G2: ='Adelgade 1'!C30 -> 0 | H2: ='Adelgade 1'!D30 -> 0 | I2: ='Adelgade 1'!E30 -> 0 | J2: ='Adelgade 1'!F30 -> 0 | K2: ='Adelgade 1'!G30 -> 0 | L2: ='Adelgade 1'!H30 -> 0 | M2: ='Adelgade 1'!I30 -> 0 | N2: ='Adelgade 1'!J30 -> 0 | ... Y2: ='Adelgade 1'!U30 -> 0 | Z2: =SUBTOTAL(109,G2:Y2) -> 0
A3: Ahornvænget 5 | B3: Fjelleruphus | C3: Daginstitutioner | D3: Gustav Silberbauer | E3: 5856 | F3: Ryslinge | G3: ='Ahornvænget 5'!C76 -> 0 | H3: ='Ahornvænget 5'!D76 -> 99000 | I3: ='Ahornvænget 5'!E76 -> 67500 | J3: ='Ahornvænget 5'!F76 -> 291540 | K3: ='Ahornvænget 5'!G76 -> 193330 | L3: ='Ahornvænget 5'!H76 -> 240120 | M3: ='Ahornvænget 5'!I76 -> 247750 | N3: ='Ahornvænget 5'!J76 -> 112300 | ... Y3: ='Ahornvænget 5'!U76 -> 95000 | Z3: =SUBTOTAL(109,G3:Y3) -> 1753040
A4: Algade 40 | B4: Ringe bibliotek | C4: Bibliotek | D4: Gustav Silberbauer | E4: 5750 | F4: Ringe | G4: ='Algade 40'!C30 -> 0 | H4: ='Algade 40'!D30 -> 0 | I4: ='Algade 40'!E30 -> 0 | J4: ='Algade 40'!F30 -> 0 | K4: ='Algade 40'!G30 -> 0 | L4: ='Algade 40'!H30 -> 0 | M4: ='Algade 40'!I30 -> 0 | N4: ='Algade 40'!J30 -> 0 | ... Y4: ='Algade 40'!U30 -> 0 | Z4: =SUBTOTAL(109,G4:Y4) -> 0
A5: Assensvej 183 | B5: Thaisen Hus | D5: Allan Kvistgaard Laursen | E5: 5750 | F5: Ringe | G5: ='Assensvej 183'!C30 -> 0 | H5: ='Assensvej 183'!D30 -> 0 | I5: ='Assensvej 183'!E30 -> 0 | J5: ='Assensvej 183'!F30 -> 0 | K5: ='Assensvej 183'!G30 -> 0 | L5: ='Assensvej 183'!H30 -> 0 | M5: ='Assensvej 183'!I30 -> 0 | N5: ='Assensvej 183'!J30 -> 0 | ... Y5: ='Assensvej 183'!U30 -> 0 | Z5: =SUBTOTAL(109,G5:Y5) -> 0
A6: Assensvej 493 | B6: Klub | D6: Kenneth Gitz | E6: 5642 | F6: Millinge | G6: ='Assensvej 493'!C30 -> 0 | H6: ='Assensvej 493'!D30 -> 0 | I6: ='Assensvej 493'!E30 -> 0 | J6: ='Assensvej 493'!F30 -> 0 | K6: ='Assensvej 493'!G30 -> 0 | L6: ='Assensvej 493'!H30 -> 0 | M6: ='Assensvej 493'!I30 -> 0 | N6: ='Assensvej 493'!J30 -> 0 | ... Y6: ='Assensvej 493'!U30 -> 0 | Z6: =SUBTOTAL(109,G6:Y6) -> 0
A7: Assensvej 497A st- B 1 th- 1 tv-C st-Dst-E st | B7: Udlejningsejendom | C7: Udlejning - Konto 11 | D7: Allan Kvistgaard Laursen | E7: 5642 | F7: Millinge | G7: ='Assensvej 497A'!C30 -> 0 | H7: ='Assensvej 497A'!D30 -> 0 | I7: ='Assensvej 497A'!E30 -> 0 | J7: ='Assensvej 497A'!F30 -> 0 | K7: ='Assensvej 497A'!G30 -> 0 | L7: ='Assensvej 497A'!H30 -> 0 | M7: ='Assensvej 497A'!I30 -> 0 | N7: ='Assensvej 497A'!J30 -> 0 | ... Y7: ='Assensvej 497A'!U30 -> 0 | Z7: =SUBTOTAL(109,G7:Y7) -> 0
A8: Assensvej 96 | B8: Bangsbo | D8: Allan Kvistgaard Laursen | E8: 5600 | F8: Faaborg | G8: ='Assensvej 96'!C30 -> 0 | H8: ='Assensvej 96'!D30 -> 0 | I8: ='Assensvej 96'!E30 -> 0 | J8: ='Assensvej 96'!F30 -> 0 | K8: ='Assensvej 96'!G30 -> 0 | L8: ='Assensvej 96'!H30 -> 0 | M8: ='Assensvej 96'!I30 -> 0 | N8: ='Assensvej 96'!J30 -> 0 | ... Y8: ='Assensvej 96'!U30 -> 0 | Z8: =SUBTOTAL(109,G8:Y8) -> 0
A9: Avernakø Hovedvejen 1 | B9: Off. Toilet - privat m. tilskud | C9: Øvrige - Konto 13 | D9: Kenneth Gitz | E9: 5602 | F9: Avernakø
A10: Avernakø(Korshavn) | B10: Off. Toilet - privat m. tilskud | C10: Øvrige - Konto 13 | D10: Kenneth Gitz | E10: 5602 | F10: Avernakø
A11: Banegårdspladsen 2 A B C D | B11: Off. Toilet | C11: Øvrige - Konto 13 | D11: Allan Kvistgaard Laursen | E11: 5600 | F11: Faaborg | G11: ='Banegårdspladsen Toilet'!C30 -> 0 | H11: ='Banegårdspladsen Toilet'!D30 -> 0 | I11: ='Banegårdspladsen Toilet'!E30 -> 0 | J11: ='Banegårdspladsen Toilet'!F30 -> 0 | K11: ='Banegårdspladsen Toilet'!G30 -> 0 | L11: ='Banegårdspladsen Toilet'!H30 -> 0 | M11: ='Banegårdspladsen Toilet'!I30 -> 0 | N11: ='Banegårdspladsen Toilet'!J30 -> 0 | ... Y11: ='Banegårdspladsen Toilet'!U30 -> 0 | Z11: =SUBTOTAL(109,G11:Y11) -> 0
A12: Banegårdspladsen 2 A B C D | B12: Gl. Banegård | C12: Øvrige - Konto 13 | D12: Anne Langelund | E12: 5600 | F12: Faaborg | G12: ='Banegårdspladsen 2 ABCD'!C30 -> 0 | H12: ='Banegårdspladsen 2 ABCD'!D30 -> 0 | I12: ='Banegårdspladsen 2 ABCD'!E30 -> 0 | J12: ='Banegårdspladsen 2 ABCD'!F30 -> 0 | K12: ='Banegårdspladsen 2 ABCD'!G30 -> 0 | L12: ='Banegårdspladsen 2 ABCD'!H30 -> 0 | M12: ='Banegårdspladsen 2 ABCD'!I30 -> 0 | N12: ='Banegårdspladsen 2 ABCD'!J30 -> 0 | ... Y12: ='Banegårdspladsen 2 ABCD'!U30 -> 0 | Z12: =SUBTOTAL(109,G12:Y12) -> 0
A13: Banegårdspladsen 2 E -F | B13: Garage | C13: Øvrige - Konto 13 | D13: Anne Langelund | E13: 5600 | F13: Faaborg | G13: ='Banegårdspladsen 2 EF'!C30 -> 0 | H13: ='Banegårdspladsen 2 EF'!D30 -> 0 | I13: ='Banegårdspladsen 2 EF'!E30 -> 0 | J13: ='Banegårdspladsen 2 EF'!F30 -> 0 | K13: ='Banegårdspladsen 2 EF'!G30 -> 0 | L13: ='Banegårdspladsen 2 EF'!H30 -> 0 | M13: ='Banegårdspladsen 2 EF'!I30 -> 0 | N13: ='Banegårdspladsen 2 EF'!J30 -> 0 | ... Y13: ='Banegårdspladsen 2 EF'!U30 -> 0 | Z13: =SUBTOTAL(109,G13:Y13) -> 0
A14: Banegårdspladsen 4 | B14: Banegårdsplads | C14: Øvrige - Konto 13 | D14: Anne Langelund | E14: 5600 | F14: Faaborg | G14: ='Banegårdspladsen 4'!C30 -> 0 | H14: ='Banegårdspladsen 4'!D30 -> 0 | I14: ='Banegårdspladsen 4'!E30 -> 0 | J14: ='Banegårdspladsen 4'!F30 -> 0 | K14: ='Banegårdspladsen 4'!G30 -> 0 | L14: ='Banegårdspladsen 4'!H30 -> 0 | M14: ='Banegårdspladsen 4'!I30 -> 0 | N14: ='Banegårdspladsen 4'!J30 -> 0 | ... Y14: ='Banegårdspladsen 4'!U30 -> 0 | Z14: =SUBTOTAL(109,G14:Y14) -> 0
A15: Banegårdspladsen 7 | B15: Helios - Biograf | C15: Øvrige - Konto 13 | D15: Allan Kvistgaard Laursen | E15: 5600 | F15: Faaborg | G15: ='Banegårdspladsen 7'!C30 -> 0 | H15: ='Banegårdspladsen 7'!D30 -> 0 | I15: ='Banegårdspladsen 7'!E30 -> 0 | J15: ='Banegårdspladsen 7'!F30 -> 0 | K15: ='Banegårdspladsen 7'!G30 -> 0 | L15: ='Banegårdspladsen 7'!H30 -> 0 | M15: ='Banegårdspladsen 7'!I30 -> 0 | N15: ='Banegårdspladsen 7'!J30 -> 0 | ... Y15: ='Banegårdspladsen 7'!U30 -> 0 | Z15: =SUBTOTAL(109,G15:Y15) -> 0
A16: Banepladsen 2 | B16: Den Gl. Station | C16: Øvrige - Konto 13 | D16: Gustav Silberbauer | E16: 5772 | F16: Kværndrup | G16: ='Banepladsen 2 '!C30 -> 0 | H16: ='Banepladsen 2 '!D30 -> 0 | I16: ='Banepladsen 2 '!E30 -> 0 | J16: ='Banepladsen 2 '!F30 -> 0 | K16: ='Banepladsen 2 '!G30 -> 0 | L16: ='Banepladsen 2 '!H30 -> 0 | M16: ='Banepladsen 2 '!I30 -> 0 | N16: ='Banepladsen 2 '!J30 -> 0 | ... Y16: ='Banepladsen 2 '!U30 -> 0 | Z16: =SUBTOTAL(109,G16:Y16) -> 0
A17: Birkelundsvej 1 | B17: Årslev Børnehave | C17: Daginstitutioner | D17: Gustav Silberbauer | E17: 5792 | F17: Årslev | G17: ='Birkelundsvej 1'!C30 -> 0 | H17: ='Birkelundsvej 1'!D30 -> 0 | I17: ='Birkelundsvej 1'!E30 -> 0 | J17: ='Birkelundsvej 1'!F30 -> 0 | K17: ='Birkelundsvej 1'!G30 -> 0 | L17: ='Birkelundsvej 1'!H30 -> 0 | M17: ='Birkelundsvej 1'!I30 -> 0 | N17: ='Birkelundsvej 1'!J30 -> 0 | ... Y17: ='Birkelundsvej 1'!U30 -> 0 | Z17: =SUBTOTAL(109,G17:Y17) -> 0
A18: Birkevej 15 | B18: MDVuns | C18: Daginstitutioner | D18: Allan Kvistgaard Laursen | E18: 5672 | F18: Broby | G18: ='Birkevej 15 (institution)'!C30 -> 0 | H18: ='Birkevej 15 (institution)'!D30 -> 0 | I18: ='Birkevej 15 (institution)'!E30 -> 0 | J18: ='Birkevej 15 (institution)'!F30 -> 0 | K18: ='Birkevej 15 (institution)'!G30 -> 0 | L18: ='Birkevej 15 (institution)'!H30 -> 0 | M18: ='Birkevej 15 (institution)'!I30 -> 0 | N18: ='Birkevej 15 (institution)'!J30 -> 0 | ... Y18: ='Birkevej 15 (institution)'!U30 -> 0 | Z18: =SUBTOTAL(109,G18:Y18) -> 0
A19: Birkevej 15 | B19: X-huset | C19: Øvrige - Konto 13 | D19: Allan Kvistgaard Laursen | E19: 5672 | F19: Broby | G19: ='Birkevej 15 (konto 13)'!C30 -> 0 | H19: ='Birkevej 15 (konto 13)'!D30 -> 0 | I19: ='Birkevej 15 (konto 13)'!E30 -> 0 | J19: ='Birkevej 15 (konto 13)'!F30 -> 0 | K19: ='Birkevej 15 (konto 13)'!G30 -> 0 | L19: ='Birkevej 15 (konto 13)'!H30 -> 0 | M19: ='Birkevej 15 (konto 13)'!I30 -> 0 | N19: ='Birkevej 15 (konto 13)'!J30 -> 0 | ... Y19: ='Birkevej 15 (konto 13)'!U30 -> 0 | Z19: =SUBTOTAL(109,G19:Y19) -> 0
A20: Bjørnø | B20: Off. Toilet - privat m. tilskud | C20: Øvrige - Konto 13 | D20: Kenneth Gitz | E20: 5600 | F20: Faaborg
A21: Broholmvej 42 | B21: Broholm børnehave | C21: Daginstitutioner | D21: Kenneth Gitz | E21: 5672 | F21: Broby | G21: ='Broholmvej 42'!C52 -> 7500 | H21: ='Broholmvej 42'!D52 -> 42750 | I21: ='Broholmvej 42'!E52 -> 20000 | J21: ='Broholmvej 42'!F52 -> 76750 | K21: ='Broholmvej 42'!G52 -> 119300 | L21: ='Broholmvej 42'!H52 -> 45500 | M21: ='Broholmvej 42'!I52 -> 501120 | N21: ='Broholmvej 42'!J52 -> 45500 | ... Y21: ='Broholmvej 42'!U52 -> 54000 | Z21: =SUBTOTAL(9,G21:Y21) -> 3245390
A22: Bryggergården 2+6 SOLGT | B22: Hjemmeplejen Faaborg og Alkohol og Misbrug | C22: Administration - Konto 10 | E22: 5600 | F22: Faaborg | G22: ='Bryggergården 2&6 '!C30 -> 0 | H22: ='Bryggergården 2&6 '!D30 -> 0 | I22: ='Bryggergården 2&6 '!E30 -> 0 | J22: ='Bryggergården 2&6 '!F30 -> 0 | K22: ='Bryggergården 2&6 '!G30 -> 0 | L22: ='Bryggergården 2&6 '!H30 -> 0 | M22: ='Bryggergården 2&6 '!I30 -> 0 | N22: ='Bryggergården 2&6 '!J30 -> 0 | ... Y22: ='Bryggergården 2&6 '!U30 -> 0 | Z22: =SUBTOTAL(109,G22:Y22) -> 0
A23: Bygmestervej 3 | B23: Udlejning Delvis | C23: Udlejning - Konto 11 | E23: 5854 | F23: Gislev | G23: ='Bygmestervej 3'!C30 -> 0 | H23: ='Bygmestervej 3'!D30 -> 0 | I23: ='Bygmestervej 3'!E30 -> 0 | J23: ='Bygmestervej 3'!F30 -> 0 | K23: ='Bygmestervej 3'!G30 -> 0 | L23: ='Bygmestervej 3'!H30 -> 0 | M23: ='Bygmestervej 3'!I30 -> 0 | N23: ='Bygmestervej 3'!J30 -> 0 | ... Y23: ='Bygmestervej 3'!U30 -> 0 | Z23: =SUBTOTAL(109,G23:Y23) -> 0
A24: Bøgebjergvej 11A | B24: Bøgebjerg Børnehus | C24: Daginstitutioner | D24: Kenneth Gitz | E24: 5600 | F24: Faaborg | G24: ='Bøgebjergvej 11A'!C30 -> 0 | H24: ='Bøgebjergvej 11A'!D30 -> 0 | I24: ='Bøgebjergvej 11A'!E30 -> 0 | J24: ='Bøgebjergvej 11A'!F30 -> 0 | K24: ='Bøgebjergvej 11A'!G30 -> 0 | L24: ='Bøgebjergvej 11A'!H30 -> 0 | M24: ='Bøgebjergvej 11A'!I30 -> 0 | N24: ='Bøgebjergvej 11A'!J30 -> 0 | ... Y24: ='Bøgebjergvej 11A'!U30 -> 0 | Z24: =SUBTOTAL(109,G24:Y24) -> 0
A25: Bøgeparken 41 | B25: Fælleshus ved udlejningsejendom | C25: Øvrige - Konto 13 | D25: Allan Kvistgaard Laursen | E25: 5792 | F25: Årslev | G25: ='Bøgeparken 41'!C30 -> 0 | H25: ='Bøgeparken 41'!D30 -> 0 | I25: ='Bøgeparken 41'!E30 -> 0 | J25: ='Bøgeparken 41'!F30 -> 0 | K25: ='Bøgeparken 41'!G30 -> 0 | L25: ='Bøgeparken 41'!H30 -> 0 | M25: ='Bøgeparken 41'!I30 -> 0 | N25: ='Bøgeparken 41'!J30 -> 0 | ... Y25: ='Bøgeparken 41'!U30 -> 0 | Z25: =SUBTOTAL(109,G25:Y25) -> 0
A26: Centrumpladsen 6 A+B | B26: Kulurzonen | D26: Gustav Silberbauer | E26: 5750 | F26: Ringe | G26: ='Centrumpladsen 6 A+B'!C30 -> 0 | H26: ='Centrumpladsen 6 A+B'!D30 -> 0 | I26: ='Centrumpladsen 6 A+B'!E30 -> 0 | J26: ='Centrumpladsen 6 A+B'!F30 -> 0 | K26: ='Centrumpladsen 6 A+B'!G30 -> 0 | L26: ='Centrumpladsen 6 A+B'!H30 -> 0 | M26: ='Centrumpladsen 6 A+B'!I30 -> 0 | N26: ='Centrumpladsen 6 A+B'!J30 -> 0 | ... Y26: ='Centrumpladsen 6 A+B'!U30 -> 0 | Z26: =SUBTOTAL(109,G26:Y26) -> 0
A27: Chr. IX’s Vej 12 | B27: Havnebadet | D27: Anne Langelund | E27: 5600 | F27: Faaborg | G27: ='Chr. IX’s Vej 12'!C30 -> 0 | H27: ='Chr. IX’s Vej 12'!D30 -> 0 | I27: ='Chr. IX’s Vej 12'!E30 -> 0 | J27: ='Chr. IX’s Vej 12'!F30 -> 0 | K27: ='Chr. IX’s Vej 12'!G30 -> 0 | L27: ='Chr. IX’s Vej 12'!H30 -> 0 | M27: ='Chr. IX’s Vej 12'!I30 -> 0 | N27: ='Chr. IX’s Vej 12'!J30 -> 0 | ... Y27: ='Chr. IX’s Vej 12'!U30 -> 0 | Z27: =SUBTOTAL(109,G27:Y27) -> 0
A28: Chr. IX’s Vej 12 | B28: Off. Toilet - privat m. tilskud | C28: Øvrige - Konto 13 | D28: Anne Langelund | E28: 5600 | F28: Faaborg
A29: Chr. IX's Vej 2 | B29: Det Hvide Pakhus | C29: Udlejning - Konto 11 | D29: Anne Langelund | E29: 5600 | F29: Faaborg | G29: ='Chr. IXs Vej 2'!C30 -> 0 | H29: ='Chr. IXs Vej 2'!D30 -> 0 | I29: ='Chr. IXs Vej 2'!E30 -> 0 | J29: ='Chr. IXs Vej 2'!F30 -> 0 | K29: ='Chr. IXs Vej 2'!G30 -> 0 | L29: ='Chr. IXs Vej 2'!H30 -> 0 | M29: ='Chr. IXs Vej 2'!I30 -> 0 | N29: ='Chr. IXs Vej 2'!J30 -> 0 | ... Y29: ='Chr. IXs Vej 2'!U30 -> 0 | Z29: =SUBTOTAL(109,G29:Y29) -> 0
A30: Damtoften 2 | B30: Damtoften 2 | C30: Daginstitutioner | D30: Anne Langelund | E30: 5600 | F30: Faaborg | G30: ='Damtoften 2'!C30 -> 0 | H30: ='Damtoften 2'!D30 -> 0 | I30: ='Damtoften 2'!E30 -> 0 | J30: ='Damtoften 2'!F30 -> 0 | K30: ='Damtoften 2'!G30 -> 0 | L30: ='Damtoften 2'!H30 -> 0 | M30: ='Damtoften 2'!I30 -> 0 | N30: ='Damtoften 2'!J30 -> 0 | ... Y30: ='Damtoften 2'!U30 -> 0 | Z30: =SUBTOTAL(109,G30:Y30) -> 0
A31: Damtoften 4 | B31: Udlejningsejendom | C31: Udlejning - Konto 11 | D31: Allan Kvistgaard Laursen | E31: 5600 | F31: Faaborg | G31: ='Damtoften 4'!C30 -> 0 | H31: ='Damtoften 4'!D30 -> 0 | I31: ='Damtoften 4'!E30 -> 0 | J31: ='Damtoften 4'!F30 -> 0 | K31: ='Damtoften 4'!G30 -> 0 | L31: ='Damtoften 4'!H30 -> 0 | M31: ='Damtoften 4'!I30 -> 0 | N31: ='Damtoften 4'!J30 -> 0 | ... Y31: ='Damtoften 4'!U30 -> 0 | Z31: =SUBTOTAL(109,G31:Y31) -> 0
A32: Diernæsvej 2 | B32: Faaborg Miniby | D32: Kenneth Gitz | E32: 5600 | F32: Faaborg | G32: ='Diernæsvej 2'!C30 -> 0 | H32: ='Diernæsvej 2'!D30 -> 0 | I32: ='Diernæsvej 2'!E30 -> 0 | J32: ='Diernæsvej 2'!F30 -> 0 | K32: ='Diernæsvej 2'!G30 -> 0 | L32: ='Diernæsvej 2'!H30 -> 0 | M32: ='Diernæsvej 2'!I30 -> 0 | N32: ='Diernæsvej 2'!J30 -> 0 | ... Y32: ='Diernæsvej 2'!U30 -> 0 | Z32: =SUBTOTAL(109,G32:Y32) -> 0
A33: Dyreborg havn | B33: Off. Toilet - privat m. tilskud | C33: Øvrige - Konto 13 | D33: Allan Kvistgaard Laursen | E33: 5600 | F33: Faaborg
A34: Egeballe 1A | B34: Myretuen | C34: Daginstitutioner | D34: Kenneth Gitz | E34: 5672 | F34: Broby | G34: ='Egeballe 1A'!C30 -> 0 | H34: ='Egeballe 1A'!D30 -> 0 | I34: ='Egeballe 1A'!E30 -> 0 | J34: ='Egeballe 1A'!F30 -> 0 | K34: ='Egeballe 1A'!G30 -> 0 | L34: ='Egeballe 1A'!H30 -> 0 | M34: ='Egeballe 1A'!I30 -> 0 | N34: ='Egeballe 1A'!J30 -> 0 | ... Y34: ='Egeballe 1A'!U30 -> 0 | Z34: =SUBTOTAL(109,G34:Y34) -> 0
A35: Egeballe 4 | B35: STU | D35: Anne Langelund | E35: 5672 | F35: Broby | G35: ='Egeballe 4'!C30 -> 0 | H35: ='Egeballe 4'!D30 -> 0 | I35: ='Egeballe 4'!E30 -> 0 | J35: ='Egeballe 4'!F30 -> 0 | K35: ='Egeballe 4'!G30 -> 0 | L35: ='Egeballe 4'!H30 -> 0 | M35: ='Egeballe 4'!I30 -> 0 | N35: ='Egeballe 4'!J30 -> 0 | ... Y35: ='Egeballe 4'!U30 -> 0 | Z35: =SUBTOTAL(109,G35:Y35) -> 0
A36: Egeballe 4A | B36: Tom bygning (tidligere bibliotek) | D36: Anne Langelund | E36: 5672 | F36: Broby | G36: ='Egeballe 4A'!C30 -> 0 | H36: ='Egeballe 4A'!D30 -> 0 | I36: ='Egeballe 4A'!E30 -> 0 | J36: ='Egeballe 4A'!F30 -> 0 | K36: ='Egeballe 4A'!G30 -> 0 | L36: ='Egeballe 4A'!H30 -> 0 | M36: ='Egeballe 4A'!I30 -> 0 | N36: ='Egeballe 4A'!J30 -> 0 | ... Y36: ='Egeballe 4A'!U30 -> 0 | Z36: =SUBTOTAL(109,G36:Y36) -> 0
A37: Egeparken 2 | B37: Egeparken 2 | C37: Udlejning - Konto 11 | D37: Anne Langelund | E37: 5772 | F37: Kværndrup | G37: ='Egeparken 2'!C30 -> 0 | H37: ='Egeparken 2'!D30 -> 0 | I37: ='Egeparken 2'!E30 -> 0 | J37: ='Egeparken 2'!F30 -> 0 | K37: ='Egeparken 2'!G30 -> 0 | L37: ='Egeparken 2'!H30 -> 0 | M37: ='Egeparken 2'!I30 -> 0 | N37: ='Egeparken 2'!J30 -> 0 | ... Y37: ='Egeparken 2'!U30 -> 0 | Z37: =SUBTOTAL(109,G37:Y37) -> 0
A38: Egeparken 62 | B38: Egeparken 62 | C38: Udlejning - Konto 11 | D38: Anne Langelund | E38: 5772 | F38: Kværndrup | G38: ='Egeparken 62'!C30 -> 0 | H38: ='Egeparken 62'!D30 -> 0 | I38: ='Egeparken 62'!E30 -> 0 | J38: ='Egeparken 62'!F30 -> 0 | K38: ='Egeparken 62'!G30 -> 0 | L38: ='Egeparken 62'!H30 -> 0 | M38: ='Egeparken 62'!I30 -> 0 | N38: ='Egeparken 62'!J30 -> 0 | ... Y38: ='Egeparken 62'!U30 -> 0 | Z38: =SUBTOTAL(109,G38:Y38) -> 0
A39: Egeparken 64 | B39: Egebo Plejecenter | C39: Plejehjem | D39: Anne Langelund | E39: 5772 | F39: Kværndrup | G39: ='Egeparken 64'!C30 -> 0 | H39: ='Egeparken 64'!D30 -> 0 | I39: ='Egeparken 64'!E30 -> 0 | J39: ='Egeparken 64'!F30 -> 0 | K39: ='Egeparken 64'!G30 -> 0 | L39: ='Egeparken 64'!H30 -> 0 | M39: ='Egeparken 64'!I30 -> 0 | N39: ='Egeparken 64'!J30 -> 0 | ... Y39: ='Egeparken 64'!U30 -> 0 | Z39: =SUBTOTAL(109,G39:Y39) -> 0
A40: Fiskerstræde, Falsled | B40: Off. Toilet - privat m. tilskud | C40: Øvrige - Konto 13 | D40: Allan Kvistgaard Laursen | E40: 5642 | F40: Millinge
...

Sheet Priskatalog
A1: Betegnelse | B1: Katalog | C1: Pris1 | D1: Pris2 | E1: Pris3 | F1: Mængde1 | G1: Mængde 2 | H1: Mængde 3 | I1: Levetid | J1: Sfb-kode | K1: Sfbbetegnelse | L1: Aktivitetkategori | M1: Interval | N1: Varighedtype | O1: Sienhedkode | P1: Fritekstmaerke | Q1: Prisindex Dato | R1: Prisindex | S1: Interval Type | T1: Tidsforbrug | U1: Dokument | V1: Priskvalitet | W1: Kontonummer | X1: Kontobetegnelse | Y1: T-prioritet
A2: Læ- og hegnsmure, eftergang af murværk og fuger | B2: 21-20.1-01 | C2: 1700 | D2: 1450 | E2: 1400 | F2: 10 | G2: 50 | H2: 100 | I2: 60 | J2: 21 | K2: Ydervægge | L2: 1 | M2: 60 | O2: m2 | P2: n | Q2: 45200 | R2: 125.9 | S2: 3 | V2: 2 | W2: 10102 | X2: Forebyggende vedl. - Udvendig | Y2: 3
A3: Facader, eftergang af murværk og fuger | B3: 21-21.1-01 | C3: 1700 | D3: 1450 | E3: 1400 | F3: 10 | G3: 50 | H3: 100 | I3: 60 | J3: 21 | K3: Ydervægge | L3: 1 | M3: 60 | O3: m2 | P3: n | Q3: 45200 | R3: 125.9 | S3: 3 | V3: 2 | W3: 10102 | X3: Forebyggende vedl. - Udvendig | Y3: 3
A4: Facader, udskiftning af dilationsfuger | B4: 21-21.1-02 | C4: 93 | D4: 83 | E4: 88 | F4: 20 | G4: 100 | H4: 200 | I4: 120 | J4: 28 | K4: Øvrige primære bygningsdele | L4: 1 | M4: 120 | O4: m | P4: n | Q4: 45200 | R4: 125.9 | S4: 3 | V4: 2 | W4: 10302 | X4: Opretning - Udvendig | Y4: 3
A5: Lyskasser, rensning | B5: 21-21.2-01 | C5: 1 | J5: 21 | K5: Ydervægge | L5: 1 | M5: 12 | O5: stk | Q5: 45200 | R5: 125.9 | S5: 3 | V5: 2 | W5: 10102 | X5: Forebyggende vedl. - Udvendig | Y5: 2
A6: Fundament, malerbehandling | B6: 21-41.1-01 | C6: 121 | D6: 105 | E6: 96 | F6: 5 | G6: 20 | H6: 50 | I6: 120 | J6: 41 | K6: Ydervægge overflader | L6: 1 | M6: 120 | O6: m2 | P6: n | Q6: 45200 | R6: 125.9 | S6: 3 | V6: 2 | W6: 10102 | X6: Forebyggende vedl. - Udvendig | Y6: 4
A7: Facader, afrensning | B7: 21-41.1-02 | C7: 46 | D7: 39 | E7: 36 | F7: 50 | G7: 200 | H7: 500 | I7: 120 | J7: 41 | K7: Ydervægge overflader | L7: 1 | M7: 120 | O7: m2 | P7: n | Q7: 45200 | R7: 125.9 | S7: 3 | V7: 2 | W7: 10102 | X7: Forebyggende vedl. - Udvendig | Y7: 4
A8: Facader, sandblæsning | B8: 21-41.1-03 | C8: 166 | D8: 145 | E8: 133 | F8: 50 | G8: 200 | H8: 500 | I8: 240 | J8: 41 | K8: Ydervægge overflader | L8: 1 | M8: 240 | O8: m2 | P8: n | Q8: 45200 | R8: 125.9 | S8: 3 | V8: 2 | W8: 10102 | X8: Forebyggende vedl. - Udvendig | Y8: 3
A9: Facader, pudsning | B9: 21-41.1-04 | C9: 249 | D9: 207 | E9: 197 | F9: 10 | G9: 50 | H9: 100 | I9: 360 | J9: 41 | K9: Ydervægge overflader | L9: 1 | M9: 360 | O9: m2 | P9: n | Q9: 45200 | R9: 125.9 | S9: 3 | V9: 2 | W9: 10102 | X9: Forebyggende vedl. - Udvendig | Y9: 3
A10: Facader, beklædning - stålplader | B10: 21-41.1-05 | C10: 285 | D10: 254 | E10: 233 | F10: 50 | G10: 200 | H10: 500 | I10: 240 | J10: 41 | K10: Ydervægge overflader | L10: 1 | M10: 240 | O10: m2 | P10: n | Q10: 45200 | R10: 125.9 | S10: 3 | V10: 2 | W10: 10302 | X10: Opretning - Udvendig | Y10: 2
A11: Facader, beklædning - aluplader | B11: 21-41.1-06 | C11: 347 | D11: 315 | E11: 306 | F11: 20 | G11: 100 | H11: 200 | I11: 360 | J11: 41 | K11: Ydervægge overflader | L11: 1 | M11: 360 | O11: m2 | P11: n | Q11: 45200 | R11: 125.9 | S11: 3 | V11: 2 | W11: 10302 | X11: Opretning - Udvendig | Y11: 2
A12: Facader, beklædning - træ | B12: 21-41.1-07 | C12: 621 | D12: 528 | E12: 497 | F12: 10 | G12: 50 | H12: 100 | I12: 300 | J12: 41 | K12: Ydervægge overflader | L12: 1 | M12: 300 | O12: m2 | P12: n | Q12: 45200 | R12: 125.9 | S12: 3 | V12: 2 | W12: 10302 | X12: Opretning - Udvendig | Y12: 2
A13: Facader, beklædning - eternit | B13: 21-41.1-08 | C13: 362 | D13: 315 | E13: 300 | F13: 10 | G13: 50 | H13: 100 | I13: 360 | J13: 41 | K13: Ydervægge overflader | L13: 1 | M13: 360 | O13: m2 | P13: n | Q13: 45200 | R13: 125.9 | S13: 3 | V13: 2 | W13: 10302 | X13: Opretning - Udvendig | Y13: 2
A14: Facader, beklædning - Fibercement | B14: 21-41.1-09 | C14: 621 | D14: 554 | E14: 500 | F14: 10 | G14: 50 | H14: 100 | I14: 360 | J14: 41 | K14: Ydervægge overflader | L14: 1 | M14: 360 | O14: m2 | P14: n | Q14: 45200 | R14: 125.9 | S14: 3 | V14: 2 | W14: 10302 | X14: Opretning - Udvendig | Y14: 2
A15: Facader, malerbehandling -tegl/beton | B15: 21-41.1-10 | C15: 124 | D15: 112 | E15: 104 | F15: 50 | G15: 200 | H15: 500 | I15: 60 | J15: 41 | K15: Ydervægge overflader | L15: 1 | M15: 60 | O15: m2 | P15: n | Q15: 45200 | R15: 125.9 | S15: 3 | V15: 2 | W15: 10102 | X15: Forebyggende vedl. - Udvendig | Y15: 3
A16: Facader, grafittibeskyttelse | B16: 21-41.1-11 | C16: 461 | D16: 414 | E16: 393 | F16: 1 | G16: 5 | H16: 10 | I16: 60 | J16: 41 | K16: Ydervægge overflader | L16: 1 | M16: 60 | O16: m2 | P16: n | Q16: 45200 | R16: 125.9 | S16: 3 | V16: 2 | W16: 10117 | X16: Forebyggende vedl. - Grafitti | Y16: 7
A17: Facader, malerbehandling - træ | B17: 21-41.1-12 | C17: 104 | D17: 93 | E17: 88 | F17: 10 | G17: 50 | H17: 100 | I17: 60 | J17: 41 | K17: Ydervægge overflader | L17: 1 | M17: 60 | O17: m2 | P17: n | Q17: 45200 | R17: 125.9 | S17: 3 | V17: 2 | W17: 10102 | X17: Forebyggende vedl. - Udvendig | Y17: 3
A18: Facader, eftergåelse før malerbeandling | B18: 21-41.1-13 | C18: 60 | D18: 55 | E18: 50 | F18: 5 | G18: 20 | H18: 100 | J18: 41 | K18: Ydervægge overflader | L18: 1 | M18: 60 | O18: m2 | Q18: 45200 | R18: 125.9 | S18: 3 | V18: 2 | W18: 10102 | X18: Forebyggende vedl. - Udvendig | Y18: 3
A19: Døre, udskiftning | B19: 31-31.2-01 | C19: 8800 | D19: 7870 | E19: 7560 | F19: 1 | G19: 5 | H19: 10 | I19: 360 | J19: 31 | K19: Ydervægge komplettering | L19: 1 | M19: 360 | O19: stk | P19: n | Q19: 45200 | R19: 125.9 | S19: 3 | V19: 2 | W19: 10302 | X19: Opretning - Udvendig | Y19: 3
A20: Døre, udskiftning - terrassedør | B20: 31-31.2-02 | C20: 7250 | D20: 6420 | E20: 6200 | F20: 1 | G20: 5 | H20: 10 | I20: 360 | J20: 31 | K20: Ydervægge komplettering | L20: 1 | M20: 360 | O20: stk | P20: n | Q20: 45200 | R20: 125.9 | S20: 3 | V20: 2 | W20: 10302 | X20: Opretning - Udvendig | Y20: 3
A21: Døre, eftergåelse før malerbeandling | B21: 31-31.2-03 | C21: 60 | D21: 55 | E21: 50 | F21: 2 | G21: 10 | H21: 20 | I21: 60 | J21: 31 | K21: Ydervægge komplettering | L21: 1 | M21: 60 | O21: m2 | P21: n | Q21: 45200 | R21: 125.9 | S21: 3 | V21: 2 | W21: 10102 | X21: Forebyggende vedl. - Udvendig | Y21: 4
A22: Døre, malerbehandling | B22: 31-31.2-04 | C22: 207 | D22: 186 | E22: 176 | F22: 5 | G22: 20 | H22: 50 | I22: 60 | J22: 41 | K22: Ydervægge overflader | L22: 1 | M22: 60 | O22: m2 | P22: n | Q22: 45200 | R22: 125.9 | S22: 3 | V22: 2 | W22: 10102 | X22: Forebyggende vedl. - Udvendig | Y22: 4
A23: Døre, service - automatiske (lovpligtig) | B23: 31-31.2-05 | C23: 2000 | D23: 1800 | E23: 1700 | F23: 2 | G23: 5 | H23: 10 | J23: 31 | K23: Ydervægge komplettering | L23: 1 | M23: 24 | O23: stk | P23: f | Q23: 45200 | R23: 125.9 | S23: 3 | V23: 2 | W23: 10101 | X23: Forebyggende vedl. - Service | Y23: 1
A24: Døre, udskiftning - automatiske | B24: 31-31.2-06 | C24: 17000 | D24: 15000 | E24: 14500 | F24: 1 | G24: 5 | H24: 10 | J24: 31 | K24: Ydervægge komplettering | L24: 1 | M24: 240 | O24: stk | P24: f | Q24: 45200 | R24: 125.9 | S24: 3 | V24: 2 | W24: 10302 | X24: Opretning - Udvendig | Y24: 3
A25: Porte, udskiftning | B25: 31-31.3-01 | C25: 1708 | D25: 1553 | E25: 1470 | F25: 6 | G25: 30 | H25: 50 | I25: 360 | J25: 31 | K25: Ydervægge komplettering | L25: 1 | M25: 360 | O25: m2 | P25: n | Q25: 45200 | R25: 125.9 | S25: 3 | V25: 2 | W25: 10302 | X25: Opretning - Udvendig | Y25: 3
A26: Porte, malerbehandling | B26: 31-31.3-02 | C26: 104 | D26: 91 | E26: 83 | F26: 10 | G26: 30 | H26: 70 | I26: 60 | J26: 41 | K26: Ydervægge overflader | L26: 1 | M26: 60 | O26: m2 | P26: n | Q26: 45200 | R26: 125.9 | S26: 3 | V26: 2 | W26: 10102 | X26: Forebyggende vedl. - Udvendig | Y26: 4
A27: Porte, service - lovpligtig | B27: 31-31.3-03 | C27: 1000 | D27: 900 | E27: 800 | F27: 2 | G27: 5 | H27: 50 | J27: 31 | K27: Ydervægge komplettering | L27: 1 | M27: 12 | O27: stk | Q27: 45200 | R27: 125.9 | S27: 3 | V27: 2 | W27: 10101 | X27: Forebyggende vedl. - Service | Y27: 1
A28: Vinduer, udskiftning - gående | B28: 31-31.4-02 | C28: 3148 | D28: 2827 | E28: 2718 | F28: 3 | G28: 15 | H28: 30 | I28: 360 | J28: 31 | K28: Ydervægge komplettering | L28: 1 | M28: 360 | O28: m2 | P28: n | Q28: 45200 | R28: 125.9 | S28: 3 | V28: 2 | W28: 10302 | X28: Opretning - Udvendig | Y28: 3
A29: Vinduer, udskiftning - danebrog 2 fag | B29: 31-31.4-03 | C29: 4867 | D29: 4453 | E29: 4297 | F29: 3 | G29: 15 | H29: 25 | I29: 360 | J29: 31 | K29: Ydervægge komplettering | L29: 1 | M29: 360 | O29: m2 | P29: n | Q29: 45200 | R29: 125.9 | S29: 3 | V29: 2 | W29: 10302 | X29: Opretning - Udvendig | Y29: 3
A30: Vinduer, eftergåelse før malerbehandling | B30: 31-31.4-05 | C30: 60 | D30: 55 | E30: 50 | F30: 2 | G30: 10 | H30: 20 | I30: 60 | J30: 31 | K30: Ydervægge komplettering | L30: 1 | M30: 60 | O30: m2 | P30: n | Q30: 45200 | R30: 125.9 | S30: 3 | V30: 2 | W30: 10102 | X30: Forebyggende vedl. - Udvendig | Y30: 3
A31: Vinduer, malerbehandling | B31: 31-31.4-06 | C31: 207 | D31: 186 | E31: 176 | F31: 5 | G31: 20 | H31: 50 | I31: 60 | J31: 41 | K31: Ydervægge overflader | L31: 1 | M31: 60 | O31: m2 | P31: n | Q31: 45200 | R31: 125.9 | S31: 3 | V31: 2 | W31: 10102 | X31: Forebyggende vedl. - Udvendig | Y31: 3
A32: Vinduer og døre, justering og smørring | B32: 31-31.4-07 | C32: 55 | D32: 35 | E32: 25 | F32: 5 | G32: 20 | H32: 50 | J32: 31 | K32: Ydervægge komplettering | L32: 1 | M32: 36 | O32: m2 | Q32: 45200 | R32: 125.9 | S32: 3 | V32: 2 | W32: 10102 | X32: Forebyggende vedl. - Udvendig | Y32: 6
A33: Vinduer, udskiftning - sålbænke | B33: 31-31.6-01 | C33: 725 | D33: 689 | E33: 658 | F33: 5 | G33: 20 | H33: 50 | I33: 600 | J33: 31 | K33: Ydervægge komplettering | L33: 1 | M33: 600 | O33: m | P33: n | Q33: 45200 | R33: 125.9 | S33: 3 | V33: 2 | W33: 10302 | X33: Opretning - Udvendig | Y33: 2
A34: Vinduer og døre, udskiftning - fuge/fugebånd | B34: 31-31.7-01 | C34: 106 | D34: 91 | E34: 85 | F34: 10 | G34: 50 | H34: 100 | I34: 180 | J34: 31 | K34: Ydervægge komplettering | L34: 1 | M34: 180 | O34: m | P34: n | Q34: 45200 | R34: 125.9 | S34: 3 | V34: 2 | W34: 10102 | X34: Forebyggende vedl. - Udvendig | Y34: 3
A35: Døre, udskiftning - Indvendige | B35: 32-32.1-01 | C35: 3500 | D35: 3200 | E35: 3000 | F35: 1 | G35: 5 | H35: 10 | I35: 360 | J35: 32 | K35: Indervægge komplettering | L35: 1 | M35: 360 | O35: stk | P35: n | Q35: 45200 | R35: 125.9 | S35: 3 | V35: 2 | W35: 10303 | X35: Opretning - Indvendig | Y35: 5
A36: Døre, udskiftning - Branddør | B36: 32-32.1-02 | C36: 8000 | D36: 6700 | E36: 6300 | F36: 1 | G36: 5 | H36: 10 | I36: 360 | J36: 32 | K36: Indervægge komplettering | L36: 1 | M36: 360 | O36: stk | Q36: 45200 | R36: 125.9 | S36: 3 | V36: 2 | W36: 10303 | X36: Opretning - Indvendig | Y36: 1
A37: Vægge, udskiftning - træbeton/akustikpaneler | B37: 4-41.1-02 | C37: 300 | D37: 260 | E37: 245 | F37: 10 | G37: 50 | H37: 100 | J37: 42 | K37: Indervægge overflader | L37: 1 | M37: 360 | O37: m2 | Q37: 45200 | R37: 125.9 | S37: 3 | V37: 2 | W37: 10303 | X37: Opretning - Indvendig | Y37: 5
A38: Gulve, udskiftning - rullende aktivitet | B38: 4-43.1-01 | C38: 460 | D38: 460 | E38: 460 | F38: 10 | G38: 50 | H38: 100 | I38: 180 | J38: 43 | K38: Dæk overflader | L38: 1 | M38: 12 | O38: m2 | P38: f | Q38: 45200 | R38: 125.9 | S38: 3 | V38: 2 | W38: 10303 | X38: Opretning - Indvendig | Y38: 3
A39: Gulve, overfladebehandling - rullende aktivitet | B39: 4-43.1-02 | C39: 130 | D39: 130 | E39: 130 | F39: 100 | G39: 200 | H39: 500 | J39: 43 | K39: Dæk overflader | L39: 1 | M39: 12 | O39: m2 | P39: f | Q39: 45200 | R39: 125.9 | S39: 3 | V39: 2 | W39: 10103 | X39: Forebyggende vedl. - Indvendig | Y39: 4
A40: Gulve, udskiftning - sportsgulv | B40: 4-43.1-03 | C40: 900 | D40: 900 | E40: 900 | F40: 100 | G40: 500 | H40: 1000 | I40: 480 | J40: 43 | K40: Dæk overflader | L40: 1 | M40: 480 | O40: m2 | P40: f | Q40: 45200 | R40: 125.9 | S40: 3 | V40: 2 | W40: 10303 | X40: Opretning - Indvendig | Y40: 3
...

Sheet 00 - Udregningsskabelon
A3: Ydervægge komplettering
A5: (31)25.10 Facade-, terrasse- og halvdøre af træ med glas at levere og montere
A6: Facadedør med fyldning nederst/1 glasfelt - Bredde x højde, 948 x 2118 mm | B6: Stk. | C6: 1 | D6: 5 | E6: 10
A7: ,01 - 3 lags energirude, 4-20-4-20-4, Uw-værdi 0,97 W/m²K | B7: Stk. | C7: 13400 | D7: 12100 | E7: 11600
A9: Facadedør med 3 glasfelter - Bredde x højde, 948 x 2118 mm
A10: ,02 - 3 lags energirude, 4-20-4-20-4, Uw-værdi 0,98 W/m²K | B10: Stk. | C10: 13500 | D10: 12100 | E10: 11600
A12: (31)29.10 Facade-, terrassedøre af træ/alu med glas at levere og montere
A13: Facadedør med fyldning nederst/1 glasfelt øverst - Bredde x højde, 948 x 2118 mm | B13: Stk. | C13: 1 | D13: 5 | E13: 10
A14: ,01 - 3 lags energirude, 4-20-4-20-4, Uw-værdi 0,97 W/m²K | B14: Stk. | C14: 15000 | D14: 13500 | E14: 13000
A16: Facadedør med 3 glasfelter - Bredde x højde, 948 x 2118 mm
A17: ,02 - 3 lags energirude, 4-20-4-20-4, Uw-værdi 0,98 W/m²K | B17: Stk. | C17: 14200 | D17: 12800 | E17: 12300
A20: (31)45.10 Vinduer af træ, fast karm, at levere og montere (3 lags)
A21: ,01 - 588 x 1188 mm - Uw - værdi 0,83 W/m²K | B21: Stk. | C21: 3740 | D21: 3330 | E21: 3190
A22: ,05 - 1188 x 1188 mm - Uw - værdi 0,73 W/m²K | B22: Stk. | C22: 5280 | D22: 4940 | E22: 4810
A23: ,06 - 1188 x 2188 mm - Uw - værdi 0,69 W/m²K | B23: Stk. | C23: 7760 | D23: 7250 | E23: 7050
A25: (31)45.12 Vinduer af træ, topstyrede, at levere og montere (3 lags)
A26: ,01 - 588 x 1188 mm - Uw - værdi 0,94 W/m²K | B26: Stk. | C26: 4970 | D26: 4640 | E26: 4520
A27: ,03 - 1188 x 1188 mm - Uw - værdi 0,81 W/m²K | B27: Stk. | C27: 6670 | D27: 6210 | E27: 6030
A28: ,04 - 1308 x 1318 mm - Uw - værdi 0,79 W/m²K | B28: Stk. | C28: 7270 | D28: 6770 | E28: 6570
A30: (31)49.10 Vinduer af træ/alu, fast karm, at levere og montere (3 lags)
A31: ,01 - 588 x 1188 mm - Uw - værdi 0,82 W/m²K | B31: Stk. | C31: 4330 | D31: 3880 | E31: 3720
A32: ,05 - 1188 x 1188 mm - Uw - værdi 0,73 W/m²K | B32: Stk. | C32: 5970 | D32: 5360 | E32: 5140
A33: ,06 - 1188 x 2118 mm - Uw - værdi 0,69 W/m²K | B33: Stk. | C33: 8810 | D33: 7930 | E33: 7610
A35: (31)49.12 Vinduer af træ/alu, topstyrede, at levere og montere (3 lags)
A36: ,01 - 588 x 1188 mm - Uw - værdi 0,94 W/m²K | B36: Stk. | C36: 5310 | D36: 4960 | E36: 4820
A37: ,03 - 1188 x 1188 mm - Uw - værdi 0,81 W/m²K | B37: Stk. | C37: 7210 | D37: 6710 | E37: 6520
A38: ,04 - 1308 x 1318 mm - Uw - værdi 0,79 W/m²K | B38: Stk. | C38: 7800 | D38: 7250 | E38: 7040
B40: Lb. m | C40: 10 | D40: 50 | E40: 100
A41: (31)45.77 Glaslister af udskifte med glaslister af fyrretræ
A42: ,04 - 16 x 15 mm med tætningsbånd | B42: Lb. m | C42: 259 | D42: 228 | E42: 216
A44: (31)86.13 Fugning omkring vinduer og døre at levere og udføre
A45: ,04 - 10 mm fugebredde - (SikaHyflex-220 Window.) | B45: Lb. m | C45: 80.2 | D45: 57.3 | E45: 52.6
A46: ,05 - 15 mm fugebredde - (SikaHyflex-220 Window.) | B46: Lb. m | C46: 87.9 | D46: 65.4 | E46: 59.4
A47: ,06 - 20 mm fugebredde - (SikaHyflex-220 Window.) | B47: Lb. m | C47: 111 | D47: 83.3 | E47: 75.9
A49: (31)86.15 Tætning af indvendige fuger omkring vinduer og døre at levere og udføre med akrylfugemasse.
A50: ,01 - 7 mm fugebredde | B50: Lb. m | C50: 52.9 | D50: 45 | E50: 42.3
A51: ,02 - 10 mm fugebredde | B51: Lb. m | C51: 58.1 | D51: 49.7 | E51: 46.8
A52: ,03 - 15 mm fugebredde | B52: Lb. m | C52: 61.3 | D52: 52.6 | E52: 49.6
A53: ,04 - 20 mm fugebredde | B53: Lb. m | C53: 79.8 | D53: 68.8 | E53: 64.9
A55: (31)86.16 Branhæmmende fuger omkring vinduer og døre at levere og udføre
...

Sheet TOM
B1: Tilbage til årsoversigt | C1: 2024 | D1: 2025 | E1: 2026 | F1: 2027 | G1: 2028 | H1: 2029 | I1: 2030 | J1: 2031 | K1: 2032 | L1: 2033 | M1: 2034 | N1: 2035 | O1: 2036 | P1: 2037 | Q1: 2038 | R1: 2039 | S1: 2040 | T1: 2041 | U1: 2042 | V1: 2043 | W1: 2044 | X1: 2045 | Y1: Total
A2: SFB nr. | B2: Udv. Vedligehold
A3: =A35 -> #N/A | B3: =B35 -> 0 | C3: =IF(C$1>=$I35,IF($M35=0,0,(IF(MOD(($I35-C$1),$M35)=0,$G35,0))),0) -> 0 | D3: =IF(D$1>=$I35,IF($M35=0,0,(IF(MOD(($I35-D$1),$M35)=0,$G35,0))),0) -> 0 | E3: =IF(E$1>=$I35,IF($M35=0,0,(IF(MOD(($I35-E$1),$M35)=0,$G35,0))),0) -> 0 | F3: =IF(F$1>=$I35,IF($M35=0,0,(IF(MOD(($I35-F$1),$M35)=0,$G35,0))),0) -> 0 | G3: =IF(G$1>=$I35,IF($M35=0,0,(IF(MOD(($I35-G$1),$M35)=0,$G35,0))),0) -> 0 | H3: =IF(H$1>=$I35,IF($M35=0,0,(IF(MOD(($I35-H$1),$M35)=0,$G35,0))),0) -> 0 | I3: =IF(I$1>=$I35,IF($M35=0,0,(IF(MOD(($I35-I$1),$M35)=0,$G35,0))),0) -> 0 | J3: =IF(J$1>=$I35,IF($M35=0,0,(IF(MOD(($I35-J$1),$M35)=0,$G35,0))),0) -> 0 | ... X3: =IF(X$1>=$I35,IF($M35=0,0,(IF(MOD(($I35-X$1),$M35)=0,$G35,0))),0) -> 0 | Y3: =SUM(C3:X3) -> 0
A4: =A36 -> #N/A | B4: =B36 -> 0 | C4: =IF(C$1>=$I36,IF($M36=0,0,(IF(MOD(($I36-C$1),$M36)=0,$G36,0))),0) -> 0 | D4: =IF(D$1>=$I36,IF($M36=0,0,(IF(MOD(($I36-D$1),$M36)=0,$G36,0))),0) -> 0 | E4: =IF(E$1>=$I36,IF($M36=0,0,(IF(MOD(($I36-E$1),$M36)=0,$G36,0))),0) -> 0 | F4: =IF(F$1>=$I36,IF($M36=0,0,(IF(MOD(($I36-F$1),$M36)=0,$G36,0))),0) -> 0 | G4: =IF(G$1>=$I36,IF($M36=0,0,(IF(MOD(($I36-G$1),$M36)=0,$G36,0))),0) -> 0 | H4: =IF(H$1>=$I36,IF($M36=0,0,(IF(MOD(($I36-H$1),$M36)=0,$G36,0))),0) -> 0 | I4: =IF(I$1>=$I36,IF($M36=0,0,(IF(MOD(($I36-I$1),$M36)=0,$G36,0))),0) -> 0 | J4: =IF(J$1>=$I36,IF($M36=0,0,(IF(MOD(($I36-J$1),$M36)=0,$G36,0))),0) -> 0 | ... X4: =IF(X$1>=$I36,IF($M36=0,0,(IF(MOD(($I36-X$1),$M36)=0,$G36,0))),0) -> 0 | Y4: =SUM(C4:X4) -> 0
A5: =A37 -> #N/A | B5: =B37 -> 0 | C5: =IF(C$1>=$I37,IF($M37=0,0,(IF(MOD(($I37-C$1),$M37)=0,$G37,0))),0) -> 0 | D5: =IF(D$1>=$I37,IF($M37=0,0,(IF(MOD(($I37-D$1),$M37)=0,$G37,0))),0) -> 0 | E5: =IF(E$1>=$I37,IF($M37=0,0,(IF(MOD(($I37-E$1),$M37)=0,$G37,0))),0) -> 0 | F5: =IF(F$1>=$I37,IF($M37=0,0,(IF(MOD(($I37-F$1),$M37)=0,$G37,0))),0) -> 0 | G5: =IF(G$1>=$I37,IF($M37=0,0,(IF(MOD(($I37-G$1),$M37)=0,$G37,0))),0) -> 0 | H5: =IF(H$1>=$I37,IF($M37=0,0,(IF(MOD(($I37-H$1),$M37)=0,$G37,0))),0) -> 0 | I5: =IF(I$1>=$I37,IF($M37=0,0,(IF(MOD(($I37-I$1),$M37)=0,$G37,0))),0) -> 0 | J5: =IF(J$1>=$I37,IF($M37=0,0,(IF(MOD(($I37-J$1),$M37)=0,$G37,0))),0) -> 0 | ... X5: =IF(X$1>=$I37,IF($M37=0,0,(IF(MOD(($I37-X$1),$M37)=0,$G37,0))),0) -> 0 | Y5: =SUM(C5:X5) -> 0
A6: =A38 -> #N/A | B6: =B38 -> 0 | C6: =IF(C$1>=$I38,IF($M38=0,0,(IF(MOD(($I38-C$1),$M38)=0,$G38,0))),0) -> 0 | D6: =IF(D$1>=$I38,IF($M38=0,0,(IF(MOD(($I38-D$1),$M38)=0,$G38,0))),0) -> 0 | E6: =IF(E$1>=$I38,IF($M38=0,0,(IF(MOD(($I38-E$1),$M38)=0,$G38,0))),0) -> 0 | F6: =IF(F$1>=$I38,IF($M38=0,0,(IF(MOD(($I38-F$1),$M38)=0,$G38,0))),0) -> 0 | G6: =IF(G$1>=$I38,IF($M38=0,0,(IF(MOD(($I38-G$1),$M38)=0,$G38,0))),0) -> 0 | H6: =IF(H$1>=$I38,IF($M38=0,0,(IF(MOD(($I38-H$1),$M38)=0,$G38,0))),0) -> 0 | I6: =IF(I$1>=$I38,IF($M38=0,0,(IF(MOD(($I38-I$1),$M38)=0,$G38,0))),0) -> 0 | J6: =IF(J$1>=$I38,IF($M38=0,0,(IF(MOD(($I38-J$1),$M38)=0,$G38,0))),0) -> 0 | ... X6: =IF(X$1>=$I38,IF($M38=0,0,(IF(MOD(($I38-X$1),$M38)=0,$G38,0))),0) -> 0 | Y6: =SUM(C6:X6) -> 0
A7: =A39 -> #N/A | B7: =B39 -> 0 | C7: =IF(C$1>=$I39,IF($M39=0,0,(IF(MOD(($I39-C$1),$M39)=0,$G39,0))),0) -> 0 | D7: =IF(D$1>=$I39,IF($M39=0,0,(IF(MOD(($I39-D$1),$M39)=0,$G39,0))),0) -> 0 | E7: =IF(E$1>=$I39,IF($M39=0,0,(IF(MOD(($I39-E$1),$M39)=0,$G39,0))),0) -> 0 | F7: =IF(F$1>=$I39,IF($M39=0,0,(IF(MOD(($I39-F$1),$M39)=0,$G39,0))),0) -> 0 | G7: =IF(G$1>=$I39,IF($M39=0,0,(IF(MOD(($I39-G$1),$M39)=0,$G39,0))),0) -> 0 | H7: =IF(H$1>=$I39,IF($M39=0,0,(IF(MOD(($I39-H$1),$M39)=0,$G39,0))),0) -> 0 | I7: =IF(I$1>=$I39,IF($M39=0,0,(IF(MOD(($I39-I$1),$M39)=0,$G39,0))),0) -> 0 | J7: =IF(J$1>=$I39,IF($M39=0,0,(IF(MOD(($I39-J$1),$M39)=0,$G39,0))),0) -> 0 | ... X7: =IF(X$1>=$I39,IF($M39=0,0,(IF(MOD(($I39-X$1),$M39)=0,$G39,0))),0) -> 0 | Y7: =SUM(C7:X7) -> 0
A8: =A40 -> #N/A | B8: =B40 -> 0 | C8: =IF(C$1>=$I40,IF($M40=0,0,(IF(MOD(($I40-C$1),$M40)=0,$G40,0))),0) -> 0 | D8: =IF(D$1>=$I40,IF($M40=0,0,(IF(MOD(($I40-D$1),$M40)=0,$G40,0))),0) -> 0 | E8: =IF(E$1>=$I40,IF($M40=0,0,(IF(MOD(($I40-E$1),$M40)=0,$G40,0))),0) -> 0 | F8: =IF(F$1>=$I40,IF($M40=0,0,(IF(MOD(($I40-F$1),$M40)=0,$G40,0))),0) -> 0 | G8: =IF(G$1>=$I40,IF($M40=0,0,(IF(MOD(($I40-G$1),$M40)=0,$G40,0))),0) -> 0 | H8: =IF(H$1>=$I40,IF($M40=0,0,(IF(MOD(($I40-H$1),$M40)=0,$G40,0))),0) -> 0 | I8: =IF(I$1>=$I40,IF($M40=0,0,(IF(MOD(($I40-I$1),$M40)=0,$G40,0))),0) -> 0 | J8: =IF(J$1>=$I40,IF($M40=0,0,(IF(MOD(($I40-J$1),$M40)=0,$G40,0))),0) -> 0 | ... X8: =IF(X$1>=$I40,IF($M40=0,0,(IF(MOD(($I40-X$1),$M40)=0,$G40,0))),0) -> 0 | Y8: =SUM(C8:X8) -> 0
A9: =A41 -> #N/A | B9: =B41 -> 0 | C9: =IF(C$1>=$I41,IF($M41=0,0,(IF(MOD(($I41-C$1),$M41)=0,$G41,0))),0) -> 0 | D9: =IF(D$1>=$I41,IF($M41=0,0,(IF(MOD(($I41-D$1),$M41)=0,$G41,0))),0) -> 0 | E9: =IF(E$1>=$I41,IF($M41=0,0,(IF(MOD(($I41-E$1),$M41)=0,$G41,0))),0) -> 0 | F9: =IF(F$1>=$I41,IF($M41=0,0,(IF(MOD(($I41-F$1),$M41)=0,$G41,0))),0) -> 0 | G9: =IF(G$1>=$I41,IF($M41=0,0,(IF(MOD(($I41-G$1),$M41)=0,$G41,0))),0) -> 0 | H9: =IF(H$1>=$I41,IF($M41=0,0,(IF(MOD(($I41-H$1),$M41)=0,$G41,0))),0) -> 0 | I9: =IF(I$1>=$I41,IF($M41=0,0,(IF(MOD(($I41-I$1),$M41)=0,$G41,0))),0) -> 0 | J9: =IF(J$1>=$I41,IF($M41=0,0,(IF(MOD(($I41-J$1),$M41)=0,$G41,0))),0) -> 0 | ... X9: =IF(X$1>=$I41,IF($M41=0,0,(IF(MOD(($I41-X$1),$M41)=0,$G41,0))),0) -> 0 | Y9: =SUM(C9:X9) -> 0
B10: =B42 -> Indv. Vedligehold
A11: =A43 -> #N/A | B11: =B43 -> 0 | C11: =IF(C$1>=$I43,IF($M43=0,0,(IF(MOD(($I43-C$1),$M43)=0,$G43,0))),0) -> 0 | D11: =IF(D$1>=$I43,IF($M43=0,0,(IF(MOD(($I43-D$1),$M43)=0,$G43,0))),0) -> 0 | E11: =IF(E$1>=$I43,IF($M43=0,0,(IF(MOD(($I43-E$1),$M43)=0,$G43,0))),0) -> 0 | F11: =IF(F$1>=$I43,IF($M43=0,0,(IF(MOD(($I43-F$1),$M43)=0,$G43,0))),0) -> 0 | G11: =IF(G$1>=$I43,IF($M43=0,0,(IF(MOD(($I43-G$1),$M43)=0,$G43,0))),0) -> 0 | H11: =IF(H$1>=$I43,IF($M43=0,0,(IF(MOD(($I43-H$1),$M43)=0,$G43,0))),0) -> 0 | I11: =IF(I$1>=$I43,IF($M43=0,0,(IF(MOD(($I43-I$1),$M43)=0,$G43,0))),0) -> 0 | J11: =IF(J$1>=$I43,IF($M43=0,0,(IF(MOD(($I43-J$1),$M43)=0,$G43,0))),0) -> 0 | ... X11: =IF(X$1>=$I43,IF($M43=0,0,(IF(MOD(($I43-X$1),$M43)=0,$G43,0))),0) -> 0 | Y11: =SUM(C11:X11) -> 0
A12: =A44 -> #N/A | B12: =B44 -> 0 | C12: =IF(C$1>=$I44,IF($M44=0,0,(IF(MOD(($I44-C$1),$M44)=0,$G44,0))),0) -> 0 | D12: =IF(D$1>=$I44,IF($M44=0,0,(IF(MOD(($I44-D$1),$M44)=0,$G44,0))),0) -> 0 | E12: =IF(E$1>=$I44,IF($M44=0,0,(IF(MOD(($I44-E$1),$M44)=0,$G44,0))),0) -> 0 | F12: =IF(F$1>=$I44,IF($M44=0,0,(IF(MOD(($I44-F$1),$M44)=0,$G44,0))),0) -> 0 | G12: =IF(G$1>=$I44,IF($M44=0,0,(IF(MOD(($I44-G$1),$M44)=0,$G44,0))),0) -> 0 | H12: =IF(H$1>=$I44,IF($M44=0,0,(IF(MOD(($I44-H$1),$M44)=0,$G44,0))),0) -> 0 | I12: =IF(I$1>=$I44,IF($M44=0,0,(IF(MOD(($I44-I$1),$M44)=0,$G44,0))),0) -> 0 | J12: =IF(J$1>=$I44,IF($M44=0,0,(IF(MOD(($I44-J$1),$M44)=0,$G44,0))),0) -> 0 | ... X12: =IF(X$1>=$I44,IF($M44=0,0,(IF(MOD(($I44-X$1),$M44)=0,$G44,0))),0) -> 0 | Y12: =SUM(C12:X12) -> 0
A13: =A45 -> #N/A | B13: =B45 -> 0 | C13: =IF(C$1>=$I45,IF($M45=0,0,(IF(MOD(($I45-C$1),$M45)=0,$G45,0))),0) -> 0 | D13: =IF(D$1>=$I45,IF($M45=0,0,(IF(MOD(($I45-D$1),$M45)=0,$G45,0))),0) -> 0 | E13: =IF(E$1>=$I45,IF($M45=0,0,(IF(MOD(($I45-E$1),$M45)=0,$G45,0))),0) -> 0 | F13: =IF(F$1>=$I45,IF($M45=0,0,(IF(MOD(($I45-F$1),$M45)=0,$G45,0))),0) -> 0 | G13: =IF(G$1>=$I45,IF($M45=0,0,(IF(MOD(($I45-G$1),$M45)=0,$G45,0))),0) -> 0 | H13: =IF(H$1>=$I45,IF($M45=0,0,(IF(MOD(($I45-H$1),$M45)=0,$G45,0))),0) -> 0 | I13: =IF(I$1>=$I45,IF($M45=0,0,(IF(MOD(($I45-I$1),$M45)=0,$G45,0))),0) -> 0 | J13: =IF(J$1>=$I45,IF($M45=0,0,(IF(MOD(($I45-J$1),$M45)=0,$G45,0))),0) -> 0 | ... X13: =IF(X$1>=$I45,IF($M45=0,0,(IF(MOD(($I45-X$1),$M45)=0,$G45,0))),0) -> 0 | Y13: =SUM(C13:X13) -> 0
A14: =A46 -> #N/A | B14: =B46 -> 0 | C14: =IF(C$1>=$I46,IF($M46=0,0,(IF(MOD(($I46-C$1),$M46)=0,$G46,0))),0) -> 0 | D14: =IF(D$1>=$I46,IF($M46=0,0,(IF(MOD(($I46-D$1),$M46)=0,$G46,0))),0) -> 0 | E14: =IF(E$1>=$I46,IF($M46=0,0,(IF(MOD(($I46-E$1),$M46)=0,$G46,0))),0) -> 0 | F14: =IF(F$1>=$I46,IF($M46=0,0,(IF(MOD(($I46-F$1),$M46)=0,$G46,0))),0) -> 0 | G14: =IF(G$1>=$I46,IF($M46=0,0,(IF(MOD(($I46-G$1),$M46)=0,$G46,0))),0) -> 0 | H14: =IF(H$1>=$I46,IF($M46=0,0,(IF(MOD(($I46-H$1),$M46)=0,$G46,0))),0) -> 0 | I14: =IF(I$1>=$I46,IF($M46=0,0,(IF(MOD(($I46-I$1),$M46)=0,$G46,0))),0) -> 0 | J14: =IF(J$1>=$I46,IF($M46=0,0,(IF(MOD(($I46-J$1),$M46)=0,$G46,0))),0) -> 0 | ... X14: =IF(X$1>=$I46,IF($M46=0,0,(IF(MOD(($I46-X$1),$M46)=0,$G46,0))),0) -> 0 | Y14: =SUM(C14:X14) -> 0
A15: =A47 -> #N/A | B15: =B47 -> 0 | C15: =IF(C$1>=$I47,IF($M47=0,0,(IF(MOD(($I47-C$1),$M47)=0,$G47,0))),0) -> 0 | D15: =IF(D$1>=$I47,IF($M47=0,0,(IF(MOD(($I47-D$1),$M47)=0,$G47,0))),0) -> 0 | E15: =IF(E$1>=$I47,IF($M47=0,0,(IF(MOD(($I47-E$1),$M47)=0,$G47,0))),0) -> 0 | F15: =IF(F$1>=$I47,IF($M47=0,0,(IF(MOD(($I47-F$1),$M47)=0,$G47,0))),0) -> 0 | G15: =IF(G$1>=$I47,IF($M47=0,0,(IF(MOD(($I47-G$1),$M47)=0,$G47,0))),0) -> 0 | H15: =IF(H$1>=$I47,IF($M47=0,0,(IF(MOD(($I47-H$1),$M47)=0,$G47,0))),0) -> 0 | I15: =IF(I$1>=$I47,IF($M47=0,0,(IF(MOD(($I47-I$1),$M47)=0,$G47,0))),0) -> 0 | J15: =IF(J$1>=$I47,IF($M47=0,0,(IF(MOD(($I47-J$1),$M47)=0,$G47,0))),0) -> 0 | ... X15: =IF(X$1>=$I47,IF($M47=0,0,(IF(MOD(($I47-X$1),$M47)=0,$G47,0))),0) -> 0 | Y15: =SUM(C15:X15) -> 0
A16: =A48 -> #N/A | B16: =B48 -> 0 | C16: =IF(C$1>=$I48,IF($M48=0,0,(IF(MOD(($I48-C$1),$M48)=0,$G48,0))),0) -> 0 | D16: =IF(D$1>=$I48,IF($M48=0,0,(IF(MOD(($I48-D$1),$M48)=0,$G48,0))),0) -> 0 | E16: =IF(E$1>=$I48,IF($M48=0,0,(IF(MOD(($I48-E$1),$M48)=0,$G48,0))),0) -> 0 | F16: =IF(F$1>=$I48,IF($M48=0,0,(IF(MOD(($I48-F$1),$M48)=0,$G48,0))),0) -> 0 | G16: =IF(G$1>=$I48,IF($M48=0,0,(IF(MOD(($I48-G$1),$M48)=0,$G48,0))),0) -> 0 | H16: =IF(H$1>=$I48,IF($M48=0,0,(IF(MOD(($I48-H$1),$M48)=0,$G48,0))),0) -> 0 | I16: =IF(I$1>=$I48,IF($M48=0,0,(IF(MOD(($I48-I$1),$M48)=0,$G48,0))),0) -> 0 | J16: =IF(J$1>=$I48,IF($M48=0,0,(IF(MOD(($I48-J$1),$M48)=0,$G48,0))),0) -> 0 | ... X16: =IF(X$1>=$I48,IF($M48=0,0,(IF(MOD(($I48-X$1),$M48)=0,$G48,0))),0) -> 0 | Y16: =SUM(C16:X16) -> 0
A17: =A49 -> #N/A | B17: =B49 -> 0 | C17: =IF(C$1>=$I49,IF($M49=0,0,(IF(MOD(($I49-C$1),$M49)=0,$G49,0))),0) -> 0 | D17: =IF(D$1>=$I49,IF($M49=0,0,(IF(MOD(($I49-D$1),$M49)=0,$G49,0))),0) -> 0 | E17: =IF(E$1>=$I49,IF($M49=0,0,(IF(MOD(($I49-E$1),$M49)=0,$G49,0))),0) -> 0 | F17: =IF(F$1>=$I49,IF($M49=0,0,(IF(MOD(($I49-F$1),$M49)=0,$G49,0))),0) -> 0 | G17: =IF(G$1>=$I49,IF($M49=0,0,(IF(MOD(($I49-G$1),$M49)=0,$G49,0))),0) -> 0 | H17: =IF(H$1>=$I49,IF($M49=0,0,(IF(MOD(($I49-H$1),$M49)=0,$G49,0))),0) -> 0 | I17: =IF(I$1>=$I49,IF($M49=0,0,(IF(MOD(($I49-I$1),$M49)=0,$G49,0))),0) -> 0 | J17: =IF(J$1>=$I49,IF($M49=0,0,(IF(MOD(($I49-J$1),$M49)=0,$G49,0))),0) -> 0 | ... X17: =IF(X$1>=$I49,IF($M49=0,0,(IF(MOD(($I49-X$1),$M49)=0,$G49,0))),0) -> 0 | Y17: =SUM(C17:X17) -> 0
B18: =B50 -> Tekniske Installationer
A19: =A51 -> #N/A | B19: =B51 -> 0 | C19: =IF(C$1>=$I51,IF($M51=0,0,(IF(MOD(($I51-C$1),$M51)=0,$G51,0))),0) -> 0 | D19: =IF(D$1>=$I51,IF($M51=0,0,(IF(MOD(($I51-D$1),$M51)=0,$G51,0))),0) -> 0 | E19: =IF(E$1>=$I51,IF($M51=0,0,(IF(MOD(($I51-E$1),$M51)=0,$G51,0))),0) -> 0 | F19: =IF(F$1>=$I51,IF($M51=0,0,(IF(MOD(($I51-F$1),$M51)=0,$G51,0))),0) -> 0 | G19: =IF(G$1>=$I51,IF($M51=0,0,(IF(MOD(($I51-G$1),$M51)=0,$G51,0))),0) -> 0 | H19: =IF(H$1>=$I51,IF($M51=0,0,(IF(MOD(($I51-H$1),$M51)=0,$G51,0))),0) -> 0 | I19: =IF(I$1>=$I51,IF($M51=0,0,(IF(MOD(($I51-I$1),$M51)=0,$G51,0))),0) -> 0 | J19: =IF(J$1>=$I51,IF($M51=0,0,(IF(MOD(($I51-J$1),$M51)=0,$G51,0))),0) -> 0 | ... X19: =IF(X$1>=$I51,IF($M51=0,0,(IF(MOD(($I51-X$1),$M51)=0,$G51,0))),0) -> 0 | Y19: =SUM(C19:X19) -> 0
A20: =A52 -> #N/A | B20: =B52 -> 0 | C20: =IF(C$1>=$I52,IF($M52=0,0,(IF(MOD(($I52-C$1),$M52)=0,$G52,0))),0) -> 0 | D20: =IF(D$1>=$I52,IF($M52=0,0,(IF(MOD(($I52-D$1),$M52)=0,$G52,0))),0) -> 0 | E20: =IF(E$1>=$I52,IF($M52=0,0,(IF(MOD(($I52-E$1),$M52)=0,$G52,0))),0) -> 0 | F20: =IF(F$1>=$I52,IF($M52=0,0,(IF(MOD(($I52-F$1),$M52)=0,$G52,0))),0) -> 0 | G20: =IF(G$1>=$I52,IF($M52=0,0,(IF(MOD(($I52-G$1),$M52)=0,$G52,0))),0) -> 0 | H20: =IF(H$1>=$I52,IF($M52=0,0,(IF(MOD(($I52-H$1),$M52)=0,$G52,0))),0) -> 0 | I20: =IF(I$1>=$I52,IF($M52=0,0,(IF(MOD(($I52-I$1),$M52)=0,$G52,0))),0) -> 0 | J20: =IF(J$1>=$I52,IF($M52=0,0,(IF(MOD(($I52-J$1),$M52)=0,$G52,0))),0) -> 0 | ... X20: =IF(X$1>=$I52,IF($M52=0,0,(IF(MOD(($I52-X$1),$M52)=0,$G52,0))),0) -> 0 | Y20: =SUM(C20:X20) -> 0
A21: =A53 -> #N/A | B21: =B53 -> 0 | C21: =IF(C$1>=$I53,IF($M53=0,0,(IF(MOD(($I53-C$1),$M53)=0,$G53,0))),0) -> 0 | D21: =IF(D$1>=$I53,IF($M53=0,0,(IF(MOD(($I53-D$1),$M53)=0,$G53,0))),0) -> 0 | E21: =IF(E$1>=$I53,IF($M53=0,0,(IF(MOD(($I53-E$1),$M53)=0,$G53,0))),0) -> 0 | F21: =IF(F$1>=$I53,IF($M53=0,0,(IF(MOD(($I53-F$1),$M53)=0,$G53,0))),0) -> 0 | G21: =IF(G$1>=$I53,IF($M53=0,0,(IF(MOD(($I53-G$1),$M53)=0,$G53,0))),0) -> 0 | H21: =IF(H$1>=$I53,IF($M53=0,0,(IF(MOD(($I53-H$1),$M53)=0,$G53,0))),0) -> 0 | I21: =IF(I$1>=$I53,IF($M53=0,0,(IF(MOD(($I53-I$1),$M53)=0,$G53,0))),0) -> 0 | J21: =IF(J$1>=$I53,IF($M53=0,0,(IF(MOD(($I53-J$1),$M53)=0,$G53,0))),0) -> 0 | ... X21: =IF(X$1>=$I53,IF($M53=0,0,(IF(MOD(($I53-X$1),$M53)=0,$G53,0))),0) -> 0 | Y21: =SUM(C21:X21) -> 0
B22: =B54 -> Sikringsanlæg
A23: =A55 -> #N/A | B23: =B55 -> 0 | C23: =IF(C$1>=$I55,IF($M55=0,0,(IF(MOD(($I55-C$1),$M55)=0,$G55,0))),0) -> 0 | D23: =IF(D$1>=$I55,IF($M55=0,0,(IF(MOD(($I55-D$1),$M55)=0,$G55,0))),0) -> 0 | E23: =IF(E$1>=$I55,IF($M55=0,0,(IF(MOD(($I55-E$1),$M55)=0,$G55,0))),0) -> 0 | F23: =IF(F$1>=$I55,IF($M55=0,0,(IF(MOD(($I55-F$1),$M55)=0,$G55,0))),0) -> 0 | G23: =IF(G$1>=$I55,IF($M55=0,0,(IF(MOD(($I55-G$1),$M55)=0,$G55,0))),0) -> 0 | H23: =IF(H$1>=$I55,IF($M55=0,0,(IF(MOD(($I55-H$1),$M55)=0,$G55,0))),0) -> 0 | I23: =IF(I$1>=$I55,IF($M55=0,0,(IF(MOD(($I55-I$1),$M55)=0,$G55,0))),0) -> 0 | J23: =IF(J$1>=$I55,IF($M55=0,0,(IF(MOD(($I55-J$1),$M55)=0,$G55,0))),0) -> 0 | ... X23: =IF(X$1>=$I55,IF($M55=0,0,(IF(MOD(($I55-X$1),$M55)=0,$G55,0))),0) -> 0 | Y23: =SUM(C23:X23) -> 0
A24: =A56 -> #N/A | B24: =B56 -> 0 | C24: =IF(C$1>=$I56,IF($M56=0,0,(IF(MOD(($I56-C$1),$M56)=0,$G56,0))),0) -> 0 | D24: =IF(D$1>=$I56,IF($M56=0,0,(IF(MOD(($I56-D$1),$M56)=0,$G56,0))),0) -> 0 | E24: =IF(E$1>=$I56,IF($M56=0,0,(IF(MOD(($I56-E$1),$M56)=0,$G56,0))),0) -> 0 | F24: =IF(F$1>=$I56,IF($M56=0,0,(IF(MOD(($I56-F$1),$M56)=0,$G56,0))),0) -> 0 | G24: =IF(G$1>=$I56,IF($M56=0,0,(IF(MOD(($I56-G$1),$M56)=0,$G56,0))),0) -> 0 | H24: =IF(H$1>=$I56,IF($M56=0,0,(IF(MOD(($I56-H$1),$M56)=0,$G56,0))),0) -> 0 | I24: =IF(I$1>=$I56,IF($M56=0,0,(IF(MOD(($I56-I$1),$M56)=0,$G56,0))),0) -> 0 | J24: =IF(J$1>=$I56,IF($M56=0,0,(IF(MOD(($I56-J$1),$M56)=0,$G56,0))),0) -> 0 | ... X24: =IF(X$1>=$I56,IF($M56=0,0,(IF(MOD(($I56-X$1),$M56)=0,$G56,0))),0) -> 0 | Y24: =SUM(C24:X24) -> 0
A25: =A57 -> #N/A | B25: =B57 -> 0 | C25: =IF(C$1>=$I57,IF($M57=0,0,(IF(MOD(($I57-C$1),$M57)=0,$G57,0))),0) -> 0 | D25: =IF(D$1>=$I57,IF($M57=0,0,(IF(MOD(($I57-D$1),$M57)=0,$G57,0))),0) -> 0 | E25: =IF(E$1>=$I57,IF($M57=0,0,(IF(MOD(($I57-E$1),$M57)=0,$G57,0))),0) -> 0 | F25: =IF(F$1>=$I57,IF($M57=0,0,(IF(MOD(($I57-F$1),$M57)=0,$G57,0))),0) -> 0 | G25: =IF(G$1>=$I57,IF($M57=0,0,(IF(MOD(($I57-G$1),$M57)=0,$G57,0))),0) -> 0 | H25: =IF(H$1>=$I57,IF($M57=0,0,(IF(MOD(($I57-H$1),$M57)=0,$G57,0))),0) -> 0 | I25: =IF(I$1>=$I57,IF($M57=0,0,(IF(MOD(($I57-I$1),$M57)=0,$G57,0))),0) -> 0 | J25: =IF(J$1>=$I57,IF($M57=0,0,(IF(MOD(($I57-J$1),$M57)=0,$G57,0))),0) -> 0 | ... X25: =IF(X$1>=$I57,IF($M57=0,0,(IF(MOD(($I57-X$1),$M57)=0,$G57,0))),0) -> 0 | Y25: =SUM(C25:X25) -> 0
B26: =B58 -> Andet
A27: =A59 -> #N/A | B27: =B59 -> 0 | C27: =IF(C$1>=$I59,IF($M59=0,0,(IF(MOD(($I59-C$1),$M59)=0,$G59,0))),0) -> 0 | D27: =IF(D$1>=$I59,IF($M59=0,0,(IF(MOD(($I59-D$1),$M59)=0,$G59,0))),0) -> 0 | E27: =IF(E$1>=$I59,IF($M59=0,0,(IF(MOD(($I59-E$1),$M59)=0,$G59,0))),0) -> 0 | F27: =IF(F$1>=$I59,IF($M59=0,0,(IF(MOD(($I59-F$1),$M59)=0,$G59,0))),0) -> 0 | G27: =IF(G$1>=$I59,IF($M59=0,0,(IF(MOD(($I59-G$1),$M59)=0,$G59,0))),0) -> 0 | H27: =IF(H$1>=$I59,IF($M59=0,0,(IF(MOD(($I59-H$1),$M59)=0,$G59,0))),0) -> 0 | I27: =IF(I$1>=$I59,IF($M59=0,0,(IF(MOD(($I59-I$1),$M59)=0,$G59,0))),0) -> 0 | J27: =IF(J$1>=$I59,IF($M59=0,0,(IF(MOD(($I59-J$1),$M59)=0,$G59,0))),0) -> 0 | ... X27: =IF(X$1>=$I59,IF($M59=0,0,(IF(MOD(($I59-X$1),$M59)=0,$G59,0))),0) -> 0 | Y27: =SUM(C27:X27) -> 0
A28: =A60 -> #N/A | B28: =B60 -> 0 | C28: =IF(C$1>=$I60,IF($M60=0,0,(IF(MOD(($I60-C$1),$M60)=0,$G60,0))),0) -> 0 | D28: =IF(D$1>=$I60,IF($M60=0,0,(IF(MOD(($I60-D$1),$M60)=0,$G60,0))),0) -> 0 | E28: =IF(E$1>=$I60,IF($M60=0,0,(IF(MOD(($I60-E$1),$M60)=0,$G60,0))),0) -> 0 | F28: =IF(F$1>=$I60,IF($M60=0,0,(IF(MOD(($I60-F$1),$M60)=0,$G60,0))),0) -> 0 | G28: =IF(G$1>=$I60,IF($M60=0,0,(IF(MOD(($I60-G$1),$M60)=0,$G60,0))),0) -> 0 | H28: =IF(H$1>=$I60,IF($M60=0,0,(IF(MOD(($I60-H$1),$M60)=0,$G60,0))),0) -> 0 | I28: =IF(I$1>=$I60,IF($M60=0,0,(IF(MOD(($I60-I$1),$M60)=0,$G60,0))),0) -> 0 | J28: =IF(J$1>=$I60,IF($M60=0,0,(IF(MOD(($I60-J$1),$M60)=0,$G60,0))),0) -> 0 | ... X28: =IF(X$1>=$I60,IF($M60=0,0,(IF(MOD(($I60-X$1),$M60)=0,$G60,0))),0) -> 0 | Y28: =SUM(C28:X28) -> 0
A29: =A61 -> #N/A | B29: =B61 -> 0 | C29: =IF(C$1>=$I61,IF($M61=0,0,(IF(MOD(($I61-C$1),$M61)=0,$G61,0))),0) -> 0 | D29: =IF(D$1>=$I61,IF($M61=0,0,(IF(MOD(($I61-D$1),$M61)=0,$G61,0))),0) -> 0 | E29: =IF(E$1>=$I61,IF($M61=0,0,(IF(MOD(($I61-E$1),$M61)=0,$G61,0))),0) -> 0 | F29: =IF(F$1>=$I61,IF($M61=0,0,(IF(MOD(($I61-F$1),$M61)=0,$G61,0))),0) -> 0 | G29: =IF(G$1>=$I61,IF($M61=0,0,(IF(MOD(($I61-G$1),$M61)=0,$G61,0))),0) -> 0 | H29: =IF(H$1>=$I61,IF($M61=0,0,(IF(MOD(($I61-H$1),$M61)=0,$G61,0))),0) -> 0 | I29: =IF(I$1>=$I61,IF($M61=0,0,(IF(MOD(($I61-I$1),$M61)=0,$G61,0))),0) -> 0 | J29: =IF(J$1>=$I61,IF($M61=0,0,(IF(MOD(($I61-J$1),$M61)=0,$G61,0))),0) -> 0 | ... X29: =IF(X$1>=$I61,IF($M61=0,0,(IF(MOD(($I61-X$1),$M61)=0,$G61,0))),0) -> 0 | Y29: =SUM(C29:X29) -> 0
B30: Total pr år | C30: =SUM(C3:C26) -> 0 | D30: =SUM(D3:D26) -> 0 | E30: =SUM(E3:E26) -> 0 | F30: =SUM(F3:F26) -> 0 | G30: =SUM(G3:G26) -> 0 | H30: =SUM(H3:H26) -> 0 | I30: =SUM(I3:I26) -> 0 | J30: =SUM(J3:J26) -> 0 | ... Y30: =SUM(Y3:Y26) -> 0
C32: Mængde | D32: Enhed | E32: Enhedspris | G32: Samlet udgift | I32: Tidligste udførelse | K32: Senest udførelse | M32: Interval | O32: Pris kvalitet | Q32: Karakter | T32: Bemærkninger
B33: Udv. Vedligehold
B34: Generelt:
A35: =VLOOKUP(B35,Priskatalog!A:J,10,FALSE) -> #N/A | G35: =C35*E35 -> 0 | N35: år
A36: =VLOOKUP(B36,Priskatalog!A:J,10,FALSE) -> #N/A | G36: =C36*E36 -> 0 | N36: år
A37: =VLOOKUP(B37,Priskatalog!A:J,10,FALSE) -> #N/A | G37: =C37*E37 -> 0 | N37: år
A38: =VLOOKUP(B38,Priskatalog!A:J,10,FALSE) -> #N/A | G38: =C38*E38 -> 0 | N38: år
A39: =VLOOKUP(B39,Priskatalog!A:J,10,FALSE) -> #N/A | G39: =C39*E39 -> 0 | N39: år
A40: =VLOOKUP(B40,Priskatalog!A:J,10,FALSE) -> #N/A | G40: =C40*E40 -> 0 | N40: år
A41: =VLOOKUP(B41,Priskatalog!A:J,10,FALSE) -> #N/A | G41: =C41*E41 -> 0 | N41: år
...

Sheet Adelgade 1
B1: Tilbage til årsoversigt | C1: 2024 | D1: 2025 | E1: 2026 | F1: 2027 | G1: 2028 | H1: 2029 | I1: 2030 | J1: 2031 | K1: 2032 | L1: 2033 | M1: 2034 | N1: 2035 | O1: 2036 | P1: 2037 | Q1: 2038 | R1: 2039 | S1: 2040 | T1: 2041 | U1: 2042 | V1: 2043 | W1: 2044 | X1: 2045 | Y1: Total
A2: SFB nr. | B2: Udv. Vedligehold
A3: =A35 -> #N/A | B3: =B35 -> 0 | C3: =IF(C$1>=$I35,IF($M35=0,0,(IF(MOD(($I35-C$1),$M35)=0,$G35,0))),0) -> 0 | D3: =IF(D$1>=$I35,IF($M35=0,0,(IF(MOD(($I35-D$1),$M35)=0,$G35,0))),0) -> 0 | E3: =IF(E$1>=$I35,IF($M35=0,0,(IF(MOD(($I35-E$1),$M35)=0,$G35,0))),0) -> 0 | F3: =IF(F$1>=$I35,IF($M35=0,0,(IF(MOD(($I35-F$1),$M35)=0,$G35,0))),0) -> 0 | G3: =IF(G$1>=$I35,IF($M35=0,0,(IF(MOD(($I35-G$1),$M35)=0,$G35,0))),0) -> 0 | H3: =IF(H$1>=$I35,IF($M35=0,0,(IF(MOD(($I35-H$1),$M35)=0,$G35,0))),0) -> 0 | I3: =IF(I$1>=$I35,IF($M35=0,0,(IF(MOD(($I35-I$1),$M35)=0,$G35,0))),0) -> 0 | J3: =IF(J$1>=$I35,IF($M35=0,0,(IF(MOD(($I35-J$1),$M35)=0,$G35,0))),0) -> 0 | ... X3: =IF(X$1>=$I35,IF($M35=0,0,(IF(MOD(($I35-X$1),$M35)=0,$G35,0))),0) -> 0 | Y3: =SUM(C3:X3) -> 0
A4: =A36 -> #N/A | B4: =B36 -> 0 | C4: =IF(C$1>=$I36,IF($M36=0,0,(IF(MOD(($I36-C$1),$M36)=0,$G36,0))),0) -> 0 | D4: =IF(D$1>=$I36,IF($M36=0,0,(IF(MOD(($I36-D$1),$M36)=0,$G36,0))),0) -> 0 | E4: =IF(E$1>=$I36,IF($M36=0,0,(IF(MOD(($I36-E$1),$M36)=0,$G36,0))),0) -> 0 | F4: =IF(F$1>=$I36,IF($M36=0,0,(IF(MOD(($I36-F$1),$M36)=0,$G36,0))),0) -> 0 | G4: =IF(G$1>=$I36,IF($M36=0,0,(IF(MOD(($I36-G$1),$M36)=0,$G36,0))),0) -> 0 | H4: =IF(H$1>=$I36,IF($M36=0,0,(IF(MOD(($I36-H$1),$M36)=0,$G36,0))),0) -> 0 | I4: =IF(I$1>=$I36,IF($M36=0,0,(IF(MOD(($I36-I$1),$M36)=0,$G36,0))),0) -> 0 | J4: =IF(J$1>=$I36,IF($M36=0,0,(IF(MOD(($I36-J$1),$M36)=0,$G36,0))),0) -> 0 | ... X4: =IF(X$1>=$I36,IF($M36=0,0,(IF(MOD(($I36-X$1),$M36)=0,$G36,0))),0) -> 0 | Y4: =SUM(C4:X4) -> 0
A5: =A37 -> #N/A | B5: =B37 -> 0 | C5: =IF(C$1>=$I37,IF($M37=0,0,(IF(MOD(($I37-C$1),$M37)=0,$G37,0))),0) -> 0 | D5: =IF(D$1>=$I37,IF($M37=0,0,(IF(MOD(($I37-D$1),$M37)=0,$G37,0))),0) -> 0 | E5: =IF(E$1>=$I37,IF($M37=0,0,(IF(MOD(($I37-E$1),$M37)=0,$G37,0))),0) -> 0 | F5: =IF(F$1>=$I37,IF($M37=0,0,(IF(MOD(($I37-F$1),$M37)=0,$G37,0))),0) -> 0 | G5: =IF(G$1>=$I37,IF($M37=0,0,(IF(MOD(($I37-G$1),$M37)=0,$G37,0))),0) -> 0 | H5: =IF(H$1>=$I37,IF($M37=0,0,(IF(MOD(($I37-H$1),$M37)=0,$G37,0))),0) -> 0 | I5: =IF(I$1>=$I37,IF($M37=0,0,(IF(MOD(($I37-I$1),$M37)=0,$G37,0))),0) -> 0 | J5: =IF(J$1>=$I37,IF($M37=0,0,(IF(MOD(($I37-J$1),$M37)=0,$G37,0))),0) -> 0 | ... X5: =IF(X$1>=$I37,IF($M37=0,0,(IF(MOD(($I37-X$1),$M37)=0,$G37,0))),0) -> 0 | Y5: =SUM(C5:X5) -> 0
A6: =A38 -> #N/A | B6: =B38 -> 0 | C6: =IF(C$1>=$I38,IF($M38=0,0,(IF(MOD(($I38-C$1),$M38)=0,$G38,0))),0) -> 0 | D6: =IF(D$1>=$I38,IF($M38=0,0,(IF(MOD(($I38-D$1),$M38)=0,$G38,0))),0) -> 0 | E6: =IF(E$1>=$I38,IF($M38=0,0,(IF(MOD(($I38-E$1),$M38)=0,$G38,0))),0) -> 0 | F6: =IF(F$1>=$I38,IF($M38=0,0,(IF(MOD(($I38-F$1),$M38)=0,$G38,0))),0) -> 0 | G6: =IF(G$1>=$I38,IF($M38=0,0,(IF(MOD(($I38-G$1),$M38)=0,$G38,0))),0) -> 0 | H6: =IF(H$1>=$I38,IF($M38=0,0,(IF(MOD(($I38-H$1),$M38)=0,$G38,0))),0) -> 0 | I6: =IF(I$1>=$I38,IF($M38=0,0,(IF(MOD(($I38-I$1),$M38)=0,$G38,0))),0) -> 0 | J6: =IF(J$1>=$I38,IF($M38=0,0,(IF(MOD(($I38-J$1),$M38)=0,$G38,0))),0) -> 0 | ... X6: =IF(X$1>=$I38,IF($M38=0,0,(IF(MOD(($I38-X$1),$M38)=0,$G38,0))),0) -> 0 | Y6: =SUM(C6:X6) -> 0
A7: =A39 -> #N/A | B7: =B39 -> 0 | C7: =IF(C$1>=$I39,IF($M39=0,0,(IF(MOD(($I39-C$1),$M39)=0,$G39,0))),0) -> 0 | D7: =IF(D$1>=$I39,IF($M39=0,0,(IF(MOD(($I39-D$1),$M39)=0,$G39,0))),0) -> 0 | E7: =IF(E$1>=$I39,IF($M39=0,0,(IF(MOD(($I39-E$1),$M39)=0,$G39,0))),0) -> 0 | F7: =IF(F$1>=$I39,IF($M39=0,0,(IF(MOD(($I39-F$1),$M39)=0,$G39,0))),0) -> 0 | G7: =IF(G$1>=$I39,IF($M39=0,0,(IF(MOD(($I39-G$1),$M39)=0,$G39,0))),0) -> 0 | H7: =IF(H$1>=$I39,IF($M39=0,0,(IF(MOD(($I39-H$1),$M39)=0,$G39,0))),0) -> 0 | I7: =IF(I$1>=$I39,IF($M39=0,0,(IF(MOD(($I39-I$1),$M39)=0,$G39,0))),0) -> 0 | J7: =IF(J$1>=$I39,IF($M39=0,0,(IF(MOD(($I39-J$1),$M39)=0,$G39,0))),0) -> 0 | ... X7: =IF(X$1>=$I39,IF($M39=0,0,(IF(MOD(($I39-X$1),$M39)=0,$G39,0))),0) -> 0 | Y7: =SUM(C7:X7) -> 0
A8: =A40 -> #N/A | B8: =B40 -> 0 | C8: =IF(C$1>=$I40,IF($M40=0,0,(IF(MOD(($I40-C$1),$M40)=0,$G40,0))),0) -> 0 | D8: =IF(D$1>=$I40,IF($M40=0,0,(IF(MOD(($I40-D$1),$M40)=0,$G40,0))),0) -> 0 | E8: =IF(E$1>=$I40,IF($M40=0,0,(IF(MOD(($I40-E$1),$M40)=0,$G40,0))),0) -> 0 | F8: =IF(F$1>=$I40,IF($M40=0,0,(IF(MOD(($I40-F$1),$M40)=0,$G40,0))),0) -> 0 | G8: =IF(G$1>=$I40,IF($M40=0,0,(IF(MOD(($I40-G$1),$M40)=0,$G40,0))),0) -> 0 | H8: =IF(H$1>=$I40,IF($M40=0,0,(IF(MOD(($I40-H$1),$M40)=0,$G40,0))),0) -> 0 | I8: =IF(I$1>=$I40,IF($M40=0,0,(IF(MOD(($I40-I$1),$M40)=0,$G40,0))),0) -> 0 | J8: =IF(J$1>=$I40,IF($M40=0,0,(IF(MOD(($I40-J$1),$M40)=0,$G40,0))),0) -> 0 | ... X8: =IF(X$1>=$I40,IF($M40=0,0,(IF(MOD(($I40-X$1),$M40)=0,$G40,0))),0) -> 0 | Y8: =SUM(C8:X8) -> 0
A9: =A41 -> #N/A | B9: =B41 -> 0 | C9: =IF(C$1>=$I41,IF($M41=0,0,(IF(MOD(($I41-C$1),$M41)=0,$G41,0))),0) -> 0 | D9: =IF(D$1>=$I41,IF($M41=0,0,(IF(MOD(($I41-D$1),$M41)=0,$G41,0))),0) -> 0 | E9: =IF(E$1>=$I41,IF($M41=0,0,(IF(MOD(($I41-E$1),$M41)=0,$G41,0))),0) -> 0 | F9: =IF(F$1>=$I41,IF($M41=0,0,(IF(MOD(($I41-F$1),$M41)=0,$G41,0))),0) -> 0 | G9: =IF(G$1>=$I41,IF($M41=0,0,(IF(MOD(($I41-G$1),$M41)=0,$G41,0))),0) -> 0 | H9: =IF(H$1>=$I41,IF($M41=0,0,(IF(MOD(($I41-H$1),$M41)=0,$G41,0))),0) -> 0 | I9: =IF(I$1>=$I41,IF($M41=0,0,(IF(MOD(($I41-I$1),$M41)=0,$G41,0))),0) -> 0 | J9: =IF(J$1>=$I41,IF($M41=0,0,(IF(MOD(($I41-J$1),$M41)=0,$G41,0))),0) -> 0 | ... X9: =IF(X$1>=$I41,IF($M41=0,0,(IF(MOD(($I41-X$1),$M41)=0,$G41,0))),0) -> 0 | Y9: =SUM(C9:X9) -> 0
B10: =B42 -> Indv. Vedligehold
A11: =A43 -> #N/A | B11: =B43 -> 0 | C11: =IF(C$1>=$I43,IF($M43=0,0,(IF(MOD(($I43-C$1),$M43)=0,$G43,0))),0) -> 0 | D11: =IF(D$1>=$I43,IF($M43=0,0,(IF(MOD(($I43-D$1),$M43)=0,$G43,0))),0) -> 0 | E11: =IF(E$1>=$I43,IF($M43=0,0,(IF(MOD(($I43-E$1),$M43)=0,$G43,0))),0) -> 0 | F11: =IF(F$1>=$I43,IF($M43=0,0,(IF(MOD(($I43-F$1),$M43)=0,$G43,0))),0) -> 0 | G11: =IF(G$1>=$I43,IF($M43=0,0,(IF(MOD(($I43-G$1),$M43)=0,$G43,0))),0) -> 0 | H11: =IF(H$1>=$I43,IF($M43=0,0,(IF(MOD(($I43-H$1),$M43)=0,$G43,0))),0) -> 0 | I11: =IF(I$1>=$I43,IF($M43=0,0,(IF(MOD(($I43-I$1),$M43)=0,$G43,0))),0) -> 0 | J11: =IF(J$1>=$I43,IF($M43=0,0,(IF(MOD(($I43-J$1),$M43)=0,$G43,0))),0) -> 0 | ... X11: =IF(X$1>=$I43,IF($M43=0,0,(IF(MOD(($I43-X$1),$M43)=0,$G43,0))),0) -> 0 | Y11: =SUM(C11:X11) -> 0
A12: =A44 -> #N/A | B12: =B44 -> 0 | C12: =IF(C$1>=$I44,IF($M44=0,0,(IF(MOD(($I44-C$1),$M44)=0,$G44,0))),0) -> 0 | D12: =IF(D$1>=$I44,IF($M44=0,0,(IF(MOD(($I44-D$1),$M44)=0,$G44,0))),0) -> 0 | E12: =IF(E$1>=$I44,IF($M44=0,0,(IF(MOD(($I44-E$1),$M44)=0,$G44,0))),0) -> 0 | F12: =IF(F$1>=$I44,IF($M44=0,0,(IF(MOD(($I44-F$1),$M44)=0,$G44,0))),0) -> 0 | G12: =IF(G$1>=$I44,IF($M44=0,0,(IF(MOD(($I44-G$1),$M44)=0,$G44,0))),0) -> 0 | H12: =IF(H$1>=$I44,IF($M44=0,0,(IF(MOD(($I44-H$1),$M44)=0,$G44,0))),0) -> 0 | I12: =IF(I$1>=$I44,IF($M44=0,0,(IF(MOD(($I44-I$1),$M44)=0,$G44,0))),0) -> 0 | J12: =IF(J$1>=$I44,IF($M44=0,0,(IF(MOD(($I44-J$1),$M44)=0,$G44,0))),0) -> 0 | ... X12: =IF(X$1>=$I44,IF($M44=0,0,(IF(MOD(($I44-X$1),$M44)=0,$G44,0))),0) -> 0 | Y12: =SUM(C12:X12) -> 0
A13: =A45 -> #N/A | B13: =B45 -> 0 | C13: =IF(C$1>=$I45,IF($M45=0,0,(IF(MOD(($I45-C$1),$M45)=0,$G45,0))),0) -> 0 | D13: =IF(D$1>=$I45,IF($M45=0,0,(IF(MOD(($I45-D$1),$M45)=0,$G45,0))),0) -> 0 | E13: =IF(E$1>=$I45,IF($M45=0,0,(IF(MOD(($I45-E$1),$M45)=0,$G45,0))),0) -> 0 | F13: =IF(F$1>=$I45,IF($M45=0,0,(IF(MOD(($I45-F$1),$M45)=0,$G45,0))),0) -> 0 | G13: =IF(G$1>=$I45,IF($M45=0,0,(IF(MOD(($I45-G$1),$M45)=0,$G45,0))),0) -> 0 | H13: =IF(H$1>=$I45,IF($M45=0,0,(IF(MOD(($I45-H$1),$M45)=0,$G45,0))),0) -> 0 | I13: =IF(I$1>=$I45,IF($M45=0,0,(IF(MOD(($I45-I$1),$M45)=0,$G45,0))),0) -> 0 | J13: =IF(J$1>=$I45,IF($M45=0,0,(IF(MOD(($I45-J$1),$M45)=0,$G45,0))),0) -> 0 | ... X13: =IF(X$1>=$I45,IF($M45=0,0,(IF(MOD(($I45-X$1),$M45)=0,$G45,0))),0) -> 0 | Y13: =SUM(C13:X13) -> 0
A14: =A46 -> #N/A | B14: =B46 -> 0 | C14: =IF(C$1>=$I46,IF($M46=0,0,(IF(MOD(($I46-C$1),$M46)=0,$G46,0))),0) -> 0 | D14: =IF(D$1>=$I46,IF($M46=0,0,(IF(MOD(($I46-D$1),$M46)=0,$G46,0))),0) -> 0 | E14: =IF(E$1>=$I46,IF($M46=0,0,(IF(MOD(($I46-E$1),$M46)=0,$G46,0))),0) -> 0 | F14: =IF(F$1>=$I46,IF($M46=0,0,(IF(MOD(($I46-F$1),$M46)=0,$G46,0))),0) -> 0 | G14: =IF(G$1>=$I46,IF($M46=0,0,(IF(MOD(($I46-G$1),$M46)=0,$G46,0))),0) -> 0 | H14: =IF(H$1>=$I46,IF($M46=0,0,(IF(MOD(($I46-H$1),$M46)=0,$G46,0))),0) -> 0 | I14: =IF(I$1>=$I46,IF($M46=0,0,(IF(MOD(($I46-I$1),$M46)=0,$G46,0))),0) -> 0 | J14: =IF(J$1>=$I46,IF($M46=0,0,(IF(MOD(($I46-J$1),$M46)=0,$G46,0))),0) -> 0 | ... X14: =IF(X$1>=$I46,IF($M46=0,0,(IF(MOD(($I46-X$1),$M46)=0,$G46,0))),0) -> 0 | Y14: =SUM(C14:X14) -> 0
