Workbook

Sheet Service  på alle anlæg
A1: Adresse | B1: Navn | C1: Placering på anlæg | D1: Anlægsnr. | E1: Leverandør | F1: Type | G1: Årstal for opsætning | H1: Gammel filter nr | I1: Nyt filter nr | J1: Antal filtre | K1: Str på filter | L1: Styring | M1: Frostsikring | N1: Luftmængde (Vent-ordning) | O1: Dato for filterskifte | P1: Dage siden skift | Q1: Person som har skiftet filtret | R1: Dato på eftersyn (VENT-ordning) | S1: Kommentar. / Anmærkninger | T1: Service | U1: Hvornår udløber kontrakt
A2: =IF(Åløkkeparken!A2="","",Åløkkeparken!A2) -> Åløkkevej 4 5672 brobyværk | B2: =IF(Åløkkeparken!G2="","",Åløkkeparken!G2) -> ??? | C2: =IF(Åløkkeparken!C2="","",Åløkkeparken!C2) -> Skunk træningssal | D2: =IF(Åløkkeparken!D2="","",Åløkkeparken!D2) -> U1 | E2: =IF(Åløkkeparken!E2="","",Åløkkeparken!E2) | F2: =IF(Åløkkeparken!F2="","",Åløkkeparken!F2) -> Boksventilator | G2: =IF(Åløkkeparken!#REF!="","",Åløkkeparken!#REF!) -> #REF! | H2: =IF(Åløkkeparken!H2="","",Åløkkeparken!H2) -> Uden filtre | I2: =IF(Åløkkeparken!I2="","",Åløkkeparken!I2) | J2: =IF(Åløkkeparken!J2="","",Åløkkeparken!J2) | K2: =IF(Åløkkeparken!K2="","",Åløkkeparken!K2) | L2: =IF(Åløkkeparken!L2="","",Åløkkeparken!L2) | M2: =IF(Åløkkeparken!M2="","",Åløkkeparken!M2) | N2: =IF(Åløkkeparken!N2="","",Åløkkeparken!N2) | O2: =IF(Åløkkeparken!O2="","",Åløkkeparken!O2) -> 45804 | ... U2: =IF(Åløkkeparken!U2="","",Åløkkeparken!U2)
A3: =IF(Åløkkeparken!A3="","",Åløkkeparken!A3) -> Åløkkevej 4 5672 brobyværk | B3: =IF(Åløkkeparken!B3="","",Åløkkeparken!B3) -> Plejehjemmet Åløkkeparken | C3: =IF(Åløkkeparken!C3="","",Åløkkeparken!C3) -> Skunk træningsal, emfang i aflastningen | D3: =IF(Åløkkeparken!D3="","",Åløkkeparken!D3) -> U2 | E3: =IF(Åløkkeparken!E3="","",Åløkkeparken!E3) | F3: =IF(Åløkkeparken!F3="","",Åløkkeparken!F3) -> Boksventilator | G3: =IF(Åløkkeparken!G3="","",Åløkkeparken!G3) -> Lindab IRE 250 C LDK Man.tp | H3: =IF(Åløkkeparken!H3="","",Åløkkeparken!H3) -> Uden filtre | ... U3: =IF(Åløkkeparken!U3="","",Åløkkeparken!U3)
A4: =IF(Åløkkeparken!A4="","",Åløkkeparken!A4) -> Åløkkevej 4 5672 brobyværk | B4: =IF(Åløkkeparken!B4="","",Åløkkeparken!B4) -> Plejehjemmet Åløkkeparken | C4: =IF(Åløkkeparken!C4="","",Åløkkeparken!C4) -> Depot i legestuen start af sencor i loft | D4: =IF(Åløkkeparken!D4="","",Åløkkeparken!D4) -> VE01 | E4: =IF(Åløkkeparken!E4="","",Åløkkeparken!E4) | F4: =IF(Åløkkeparken!F4="","",Åløkkeparken!F4) -> Centrale agregregater | G4: =IF(Åløkkeparken!G4="","",Åløkkeparken!G4) -> CombiAir 550 L Luxe | H4: =IF(Åløkkeparken!H4="","",Åløkkeparken!H4) -> 16890 | ... U4: =IF(Åløkkeparken!U4="","",Åløkkeparken!U4)
A5: =IF(Åløkkeparken!A5="","",Åløkkeparken!A5) -> Åløkkevej 4 5672 brobyværk | B5: =IF(Åløkkeparken!B5="","",Åløkkeparken!B5) -> Plejehjemmet Åløkkeparken | C5: =IF(Åløkkeparken!C5="","",Åløkkeparken!C5) -> Loft over daghjem | D5: =IF(Åløkkeparken!D5="","",Åløkkeparken!D5) -> VE02 | E5: =IF(Åløkkeparken!E5="","",Åløkkeparken!E5) | F5: =IF(Åløkkeparken!F5="","",Åløkkeparken!F5) -> Centrale agregregater | G5: =IF(Åløkkeparken!G5="","",Åløkkeparken!G5) | H5: =IF(Åløkkeparken!H5="","",Åløkkeparken!H5) -> 1250247 | ... U5: =IF(Åløkkeparken!U5="","",Åløkkeparken!U5)
A6: =IF(Åløkkeparken!A6="","",Åløkkeparken!A6) -> Åløkkevej 4 5672 brobyværk | B6: =IF(Åløkkeparken!G7="","",Åløkkeparken!G7) -> Exhausto V160 Ecopleat G 0155 | C6: =IF(Åløkkeparken!C6="","",Åløkkeparken!C6) -> Flat tag ved hus B | D6: =IF(Åløkkeparken!D6="","",Åløkkeparken!D6) -> VE03 | E6: =IF(Åløkkeparken!E6="","",Åløkkeparken!E6) -> Camfil | F6: =IF(Åløkkeparken!F6="","",Åløkkeparken!F6) -> Centrale agregregater | G6: =IF(Åløkkeparken!G6="","",Åløkkeparken!G6) -> Enervent Hi-Flo G 1060 | H6: =IF(Åløkkeparken!H6="","",Åløkkeparken!H6) -> 1015953 | I6: =IF(Åløkkeparken!I6="","",Åløkkeparken!I6) -> 1015953 | J6: =IF(Åløkkeparken!J6="","",Åløkkeparken!J6) -> 2 | ... U6: =IF(Åløkkeparken!U6="","",Åløkkeparken!U6)
A7: =IF(Åløkkeparken!A7="","",Åløkkeparken!A7) -> Åløkkevej 4 5672 brobyværk | B7: =IF(Åløkkeparken!G8="","",Åløkkeparken!G8) -> Heru 130 Hi-Flo G 160 | C7: =IF(Åløkkeparken!C7="","",Åløkkeparken!C7) -> Loft over storkøkken | D7: =IF(Åløkkeparken!D7="","",Åløkkeparken!D7) -> VE04 | E7: =IF(Åløkkeparken!E7="","",Åløkkeparken!E7) -> Camfil | F7: =IF(Åløkkeparken!F7="","",Åløkkeparken!F7) -> Centrale agregregater | G7: =IF(Åløkkeparken!#REF!="","",Åløkkeparken!#REF!) -> #REF! | H7: =IF(Åløkkeparken!H7="","",Åløkkeparken!H7) -> 211835-L | I7: =IF(Åløkkeparken!I7="","",Åløkkeparken!I7) -> 1112979 | J7: =IF(Åløkkeparken!J7="","",Åløkkeparken!J7) -> 2 | K7: =IF(Åløkkeparken!K7="","",Åløkkeparken!K7) -> 838x700x96 | L7: =IF(Åløkkeparken!L7="","",Åløkkeparken!L7) | M7: =IF(Åløkkeparken!M7="","",Åløkkeparken!M7) | N7: =IF(Åløkkeparken!N7="","",Åløkkeparken!N7) | O7: =IF(Åløkkeparken!O7="","",Åløkkeparken!O7) -> 45804 | ... U7: =IF(Åløkkeparken!U7="","",Åløkkeparken!U7)
A8: =IF(Åløkkeparken!A8="","",Åløkkeparken!A8) -> Åløkkevej 4 5672 brobyværk | B8: =IF(Åløkkeparken!G9="","",Åløkkeparken!G9) | C8: =IF(Åløkkeparken!C8="","",Åløkkeparken!C8) -> Skunk træningssal | D8: =IF(Åløkkeparken!D8="","",Åløkkeparken!D8) -> VE05 | E8: =IF(Åløkkeparken!E8="","",Åløkkeparken!E8) -> Camfil | F8: =IF(Åløkkeparken!F8="","",Åløkkeparken!F8) -> Centrale agregregater | G8: =IF(Åløkkeparken!#REF!="","",Åløkkeparken!#REF!) -> #REF! | H8: =IF(Åløkkeparken!H8="","",Åløkkeparken!H8) -> 1015811 | I8: =IF(Åløkkeparken!I8="","",Åløkkeparken!I8) -> 1015811 | J8: =IF(Åløkkeparken!J8="","",Åløkkeparken!J8) -> 2 | K8: =IF(Åløkkeparken!K8="","",Åløkkeparken!K8) -> 205x468x250-3-25 | L8: =IF(Åløkkeparken!L8="","",Åløkkeparken!L8) | M8: =IF(Åløkkeparken!M8="","",Åløkkeparken!M8) | N8: =IF(Åløkkeparken!N8="","",Åløkkeparken!N8) | O8: =IF(Åløkkeparken!O8="","",Åløkkeparken!O8) -> 45804 | ... U8: =IF(Åløkkeparken!U8="","",Åløkkeparken!U8)
A9: =IF(Åløkkeparken!A9="","",Åløkkeparken!A9) -> Åløkkevej 4 5672 brobyværk | B9: =IF(Åløkkeparken!B9="","",Åløkkeparken!B9) -> Plejehjemmet Åløkkeparken | C9: =IF(Åløkkeparken!C9="","",Åløkkeparken!C9) -> Møderum bagerste rum på 1 sal | D9: =IF(Åløkkeparken!D9="","",Åløkkeparken!D9) -> VE06 | E9: =IF(Åløkkeparken!E9="","",Åløkkeparken!E9) | F9: =IF(Åløkkeparken!F9="","",Åløkkeparken!F9) -> De-Centrale agregregater | G9: =IF(Åløkkeparken!#REF!="","",Åløkkeparken!#REF!) -> #REF! | H9: =IF(Åløkkeparken!H9="","",Åløkkeparken!H9) -> ? | I9: =IF(Åløkkeparken!I9="","",Åløkkeparken!I9) -> 100483 | J9: =IF(Åløkkeparken!J9="","",Åløkkeparken!J9) -> 2 | K9: =IF(Åløkkeparken!K9="","",Åløkkeparken!K9) -> 150x310x360/2p | L9: =IF(Åløkkeparken!L9="","",Åløkkeparken!L9) | M9: =IF(Åløkkeparken!M9="","",Åløkkeparken!M9) | N9: =IF(Åløkkeparken!N9="","",Åløkkeparken!N9) | O9: =IF(Åløkkeparken!O9="","",Åløkkeparken!O9) -> 45881 | ... U9: =IF(Åløkkeparken!U9="","",Åløkkeparken!U9)
A10: =IF(Åløkkeparken!A10="","",Åløkkeparken!A10) -> Åløkkevej 4 5672 brobyværk | B10: =IF(Åløkkeparken!B10="","",Åløkkeparken!B10) -> Plejehjemmet Åløkkeparken | C10: =IF(Åløkkeparken!C10="","",Åløkkeparken!C10) -> Skunk overfor ergoteapeuternes kontor | D10: =IF(Åløkkeparken!D10="","",Åløkkeparken!D10) -> VE07 | E10: =IF(Åløkkeparken!E10="","",Åløkkeparken!E10) | F10: =IF(Åløkkeparken!F10="","",Åløkkeparken!F10) -> Centrale agregregater | G10: =IF(Åløkkeparken!G10="","",Åløkkeparken!G10) -> ??? | H10: =IF(Åløkkeparken!H10="","",Åløkkeparken!H10) -> Uden filtre | ... U10: =IF(Åløkkeparken!U10="","",Åløkkeparken!U10)
A11: =IF('Nr.Broby. Gl. Rådhus'!A2="","",'Nr.Broby. Gl. Rådhus'!A2) -> Østeragade | B11: =IF('Nr.Broby. Gl. Rådhus'!B2="","",'Nr.Broby. Gl. Rådhus'!B2) -> Broby Gl. Rådhus | C11: =IF('Nr.Broby. Gl. Rådhus'!C2="","",'Nr.Broby. Gl. Rådhus'!C2) -> KÆLDER | D11: =IF('Nr.Broby. Gl. Rådhus'!D2="","",'Nr.Broby. Gl. Rådhus'!D2) -> VE01 | E11: =IF('Nr.Broby. Gl. Rådhus'!E2="","",'Nr.Broby. Gl. Rådhus'!E2) | F11: =IF('Nr.Broby. Gl. Rådhus'!F2="","",'Nr.Broby. Gl. Rådhus'!F2) -> DANVENT SPAR 20. PROD.NR. 0900-42325-2 | G11: =IF('Nr.Broby. Gl. Rådhus'!G2="","",'Nr.Broby. Gl. Rådhus'!G2) | H11: =IF('Nr.Broby. Gl. Rådhus'!H2="","",'Nr.Broby. Gl. Rådhus'!H2) -> 1013684 | ... U11: =IF('Nr.Broby. Gl. Rådhus'!U2="","",'Nr.Broby. Gl. Rådhus'!U2)
A12: =IF('Nr.Broby. Gl. Rådhus'!A3="","",'Nr.Broby. Gl. Rådhus'!A3) -> Østeragade | B12: =IF('Nr.Broby. Gl. Rådhus'!B3="","",'Nr.Broby. Gl. Rådhus'!B3) -> Broby Gl. Rådhus | C12: =IF('Nr.Broby. Gl. Rådhus'!C3="","",'Nr.Broby. Gl. Rådhus'!C3) -> KÆLDER | D12: =IF('Nr.Broby. Gl. Rådhus'!D3="","",'Nr.Broby. Gl. Rådhus'!D3) -> VE01 | E12: =IF('Nr.Broby. Gl. Rådhus'!E3="","",'Nr.Broby. Gl. Rådhus'!E3) | F12: =IF('Nr.Broby. Gl. Rådhus'!F3="","",'Nr.Broby. Gl. Rådhus'!F3) -> DANVENT SPAR 20. PROD.NR. 0900-42325-2 | G12: =IF('Nr.Broby. Gl. Rådhus'!G3="","",'Nr.Broby. Gl. Rådhus'!G3) | H12: =IF('Nr.Broby. Gl. Rådhus'!H3="","",'Nr.Broby. Gl. Rådhus'!H3) -> 1013684 | ... U12: =IF('Nr.Broby. Gl. Rådhus'!U3="","",'Nr.Broby. Gl. Rådhus'!U3)
A13: =IF('Nr.Broby. Gl. Rådhus'!A4="","",'Nr.Broby. Gl. Rådhus'!A4) -> Østeragade | B13: =IF('Nr.Broby. Gl. Rådhus'!B4="","",'Nr.Broby. Gl. Rådhus'!B4) -> Broby Gl. Rådhus | C13: =IF('Nr.Broby. Gl. Rådhus'!C4="","",'Nr.Broby. Gl. Rådhus'!C4) -> LOFT | D13: =IF('Nr.Broby. Gl. Rådhus'!D4="","",'Nr.Broby. Gl. Rådhus'!D4) -> VE02 | E13: =IF('Nr.Broby. Gl. Rådhus'!E4="","",'Nr.Broby. Gl. Rådhus'!E4) | F13: =IF('Nr.Broby. Gl. Rådhus'!F4="","",'Nr.Broby. Gl. Rådhus'!F4) -> SYSTEMAIR DANVENT DV TIME 25 PROD. NR. 1208-69475-1 | G13: =IF('Nr.Broby. Gl. Rådhus'!G4="","",'Nr.Broby. Gl. Rådhus'!G4) | H13: =IF('Nr.Broby. Gl. Rådhus'!H4="","",'Nr.Broby. Gl. Rådhus'!H4) -> 1013259 | ... U13: =IF('Nr.Broby. Gl. Rådhus'!U4="","",'Nr.Broby. Gl. Rådhus'!U4)
A14: =IF('Nr.Broby. Gl. Rådhus'!A5="","",'Nr.Broby. Gl. Rådhus'!A5) -> Østeragade | B14: =IF('Nr.Broby. Gl. Rådhus'!B5="","",'Nr.Broby. Gl. Rådhus'!B5) -> Broby Gl. Rådhus | C14: =IF('Nr.Broby. Gl. Rådhus'!C5="","",'Nr.Broby. Gl. Rådhus'!C5) -> LOFT | D14: =IF('Nr.Broby. Gl. Rådhus'!D5="","",'Nr.Broby. Gl. Rådhus'!D5) -> VE02 | E14: =IF('Nr.Broby. Gl. Rådhus'!E5="","",'Nr.Broby. Gl. Rådhus'!E5) | F14: =IF('Nr.Broby. Gl. Rådhus'!F5="","",'Nr.Broby. Gl. Rådhus'!F5) -> SYSTEMAIR DANVENT DV TIME 25 PROD. NR. 1208-69475-1 | G14: =IF('Nr.Broby. Gl. Rådhus'!G5="","",'Nr.Broby. Gl. Rådhus'!G5) | H14: =IF('Nr.Broby. Gl. Rådhus'!H5="","",'Nr.Broby. Gl. Rådhus'!H5) -> 1013247 | ... U14: =IF('Nr.Broby. Gl. Rådhus'!U5="","",'Nr.Broby. Gl. Rådhus'!U5)
A15: =IF('motorikken klatretræet'!A5="","",'motorikken klatretræet'!A5) -> Torpegårdsvej 2a 5792 Årslev | B15: =IF('motorikken klatretræet'!B5="","",'motorikken klatretræet'!B5) -> Klatretræet | C15: =IF('motorikken klatretræet'!C5="","",'motorikken klatretræet'!C5) -> Loftet | D15: =IF('motorikken klatretræet'!D5="","",'motorikken klatretræet'!D5) -> 157628/03 | E15: =IF('motorikken klatretræet'!E5="","",'motorikken klatretræet'!E5) -> VENT ORDNINGEN | F15: =IF('motorikken klatretræet'!F5="","",'motorikken klatretræet'!F5) -> VEX150HL EC | G15: =IF('motorikken klatretræet'!G5="","",'motorikken klatretræet'!G5) -> 2022 | H15: =IF('motorikken klatretræet'!H5="","",'motorikken klatretræet'!H5) -> 1104755-23577500 | ... U15: =IF('motorikken klatretræet'!U5="","",'motorikken klatretræet'!U5)
A16: =IF('Øhavsskolen Uglen'!A18="","",'Øhavsskolen Uglen'!A18) -> Toftegårdsvej 7 | B16: =IF('Øhavsskolen Uglen'!B18="","",'Øhavsskolen Uglen'!B18) -> Øhavsskolerne afd. Uglen | C16: =IF('Øhavsskolen Uglen'!C18="","",'Øhavsskolen Uglen'!C18) -> hallen køber selv til den | D16: =IF('Øhavsskolen Uglen'!D18="","",'Øhavsskolen Uglen'!D18) -> ve 10 | E16: =IF('Øhavsskolen Uglen'!E18="","",'Øhavsskolen Uglen'!E18) | F16: =IF('Øhavsskolen Uglen'!F18="","",'Øhavsskolen Uglen'!F18) | G16: =IF('Øhavsskolen Uglen'!G18="","",'Øhavsskolen Uglen'!G18) | H16: =IF('Øhavsskolen Uglen'!H18="","",'Øhavsskolen Uglen'!H18) -> vi kiipper selv filter til | I16: =IF('Øhavsskolen Uglen'!H18="","",'Øhavsskolen Uglen'!H18) -> vi kiipper selv filter til | J16: =IF('Øhavsskolen Uglen'!J18="","",'Øhavsskolen Uglen'!J18) -> 2 | K16: =IF('Øhavsskolen Uglen'!K18="","",'Øhavsskolen Uglen'!K18) -> 860 x 750 | L16: =IF('Øhavsskolen Uglen'!L18="","",'Øhavsskolen Uglen'!L18) -> NEJ | M16: =IF('Øhavsskolen Uglen'!M18="","",'Øhavsskolen Uglen'!M18) | N16: =IF('Øhavsskolen Uglen'!N18="","",'Øhavsskolen Uglen'!N18) | O16: =IF('Øhavsskolen Uglen'!O18="","",'Øhavsskolen Uglen'!O18) -> 45803 | P16: =IF('Øhavsskolen Uglen'!P18="","",'Øhavsskolen Uglen'!P18) -> -234 | Q16: =IF('Øhavsskolen Uglen'!Q18="","",'Øhavsskolen Uglen'!Q18) -> Per / Kjeld | ... U16: =IF('Øhavsskolen Uglen'!U18="","",'Øhavsskolen Uglen'!U18)
A17: =IF('Øhavsskolen Uglen'!A20="","",'Øhavsskolen Uglen'!A20) -> Toftegårdsvej 7 | B17: =IF('Øhavsskolen Uglen'!B20="","",'Øhavsskolen Uglen'!B20) -> Øhavsskolerne afd. Uglen | C17: =IF('Øhavsskolen Uglen'!C20="","",'Øhavsskolen Uglen'!C20) -> Blok 1 på taget | D17: =IF('Øhavsskolen Uglen'!D20="","",'Øhavsskolen Uglen'!D20) -> VE11 | E17: =IF('Øhavsskolen Uglen'!E20="","",'Øhavsskolen Uglen'!E20) -> JS Ventilation a/s | F17: =IF('Øhavsskolen Uglen'!F20="","",'Øhavsskolen Uglen'!F20) -> Geniox Core 18 | G17: =IF('Øhavsskolen Uglen'!G20="","",'Øhavsskolen Uglen'!G20) -> 2023 | H17: =IF('Øhavsskolen Uglen'!H20="","",'Øhavsskolen Uglen'!H20) -> 308603 /GFP 76460801 | ... U17: =IF('Øhavsskolen Uglen'!U20="","",'Øhavsskolen Uglen'!U20)
A18: =IF('Øhavsskolen Uglen'!A22="","",'Øhavsskolen Uglen'!A22) -> Toftegårdsvej 7 | B18: =IF('Øhavsskolen Uglen'!B22="","",'Øhavsskolen Uglen'!B22) -> Øhavsskolerne afd. Uglen | C18: =IF('Øhavsskolen Uglen'!C22="","",'Øhavsskolen Uglen'!C22) -> Blok 1 på taget | D18: =IF('Øhavsskolen Uglen'!D22="","",'Øhavsskolen Uglen'!D22) -> VE11 | E18: =IF('Øhavsskolen Uglen'!E22="","",'Øhavsskolen Uglen'!E22) -> JS Ventilation a/s | F18: =IF('Øhavsskolen Uglen'!F22="","",'Øhavsskolen Uglen'!F22) -> Geniox Core 18 | G18: =IF('Øhavsskolen Uglen'!G22="","",'Øhavsskolen Uglen'!G22) -> 2023 | H18: =IF('Øhavsskolen Uglen'!H22="","",'Øhavsskolen Uglen'!H22) -> 305245 / MPG 56460601 | ... U18: =IF('Øhavsskolen Uglen'!U22="","",'Øhavsskolen Uglen'!U22)
A19: =IF('Øhavsskolen Uglen'!A25="","",'Øhavsskolen Uglen'!A25) -> Toftegårdsvej 7 | B19: =IF('Øhavsskolen Uglen'!B25="","",'Øhavsskolen Uglen'!B25) -> Øhavsskolerne afd. Uglen | C19: =IF('Øhavsskolen Uglen'!C25="","",'Øhavsskolen Uglen'!C25) -> Blok 6 på taget | D19: =IF('Øhavsskolen Uglen'!D25="","",'Øhavsskolen Uglen'!D25) -> VE61 | E19: =IF('Øhavsskolen Uglen'!E25="","",'Øhavsskolen Uglen'!E25) -> JS Ventilation a/s | F19: =IF('Øhavsskolen Uglen'!F25="","",'Øhavsskolen Uglen'!F25) -> Geniox Core 16 | G19: =IF('Øhavsskolen Uglen'!G25="","",'Øhavsskolen Uglen'!G25) -> 2023 | H19: =IF('Øhavsskolen Uglen'!H25="","",'Øhavsskolen Uglen'!H25) -> 308600 / GFP 75660601 | ... U19: =IF('Øhavsskolen Uglen'!U25="","",'Øhavsskolen Uglen'!U25)
A20: =IF('Øhavsskolen Uglen'!A26="","",'Øhavsskolen Uglen'!A26) -> Toftegårdsvej 7 | B20: =IF('Øhavsskolen Uglen'!B26="","",'Øhavsskolen Uglen'!B26) -> Øhavsskolerne afd. Uglen | C20: =IF('Øhavsskolen Uglen'!C26="","",'Øhavsskolen Uglen'!C26) -> Blok 6 på taget | D20: =IF('Øhavsskolen Uglen'!D26="","",'Øhavsskolen Uglen'!D26) -> VE61 | E20: =IF('Øhavsskolen Uglen'!E26="","",'Øhavsskolen Uglen'!E26) -> JS Ventilation a/s | F20: =IF('Øhavsskolen Uglen'!F26="","",'Øhavsskolen Uglen'!F26) -> Geniox Core 16 | G20: =IF('Øhavsskolen Uglen'!G26="","",'Øhavsskolen Uglen'!G26) -> 2023 | H20: =IF('Øhavsskolen Uglen'!H26="","",'Øhavsskolen Uglen'!H26) -> 310621 / MPG 55601 | ... U20: =IF('Øhavsskolen Uglen'!U26="","",'Øhavsskolen Uglen'!U26)
A21: =IF('Øhavsskolen Uglen'!A21="","",'Øhavsskolen Uglen'!A21) -> Toftegårdsvej 7 | B21: =IF('Øhavsskolen Uglen'!B21="","",'Øhavsskolen Uglen'!B21) -> Øhavsskolerne afd. Uglen | C21: =IF('Øhavsskolen Uglen'!C21="","",'Øhavsskolen Uglen'!C21) -> Blok 1 på taget | D21: =IF('Øhavsskolen Uglen'!D21="","",'Øhavsskolen Uglen'!D21) -> VE11 | E21: =IF('Øhavsskolen Uglen'!E21="","",'Øhavsskolen Uglen'!E21) -> JS Ventilation a/s | F21: =IF('Øhavsskolen Uglen'!F21="","",'Øhavsskolen Uglen'!F21) -> Geniox Core 18 | G21: =IF('Øhavsskolen Uglen'!G21="","",'Øhavsskolen Uglen'!G21) -> 2023 | H21: =IF('Øhavsskolen Uglen'!H21="","",'Øhavsskolen Uglen'!H21) -> 297307 / MPP 5408 | ... U21: =IF('Øhavsskolen Uglen'!U21="","",'Øhavsskolen Uglen'!U21)
A22: =IF('Øhavsskolen Uglen'!A23="","",'Øhavsskolen Uglen'!A23) -> Toftegårdsvej 7 | B22: =IF('Øhavsskolen Uglen'!B23="","",'Øhavsskolen Uglen'!B23) -> Øhavsskolerne afd. Uglen | C22: =IF('Øhavsskolen Uglen'!C23="","",'Øhavsskolen Uglen'!C23) -> Blok 1 på taget | D22: =IF('Øhavsskolen Uglen'!D23="","",'Øhavsskolen Uglen'!D23) -> VE11 | E22: =IF('Øhavsskolen Uglen'!E23="","",'Øhavsskolen Uglen'!E23) -> JS Ventilation a/s | F22: =IF('Øhavsskolen Uglen'!F23="","",'Øhavsskolen Uglen'!F23) -> Geniox Core 18 | G22: =IF('Øhavsskolen Uglen'!G23="","",'Øhavsskolen Uglen'!G23) -> 2023 | H22: =IF('Øhavsskolen Uglen'!H23="","",'Øhavsskolen Uglen'!H23) -> 307291 / MPG 55414 | ... U22: =IF('Øhavsskolen Uglen'!U23="","",'Øhavsskolen Uglen'!U23)
A23: =IF('Øhavsskolen Uglen'!A2="","",'Øhavsskolen Uglen'!A2) -> Toftegårdsvej 7 | B23: =IF('Øhavsskolen Uglen'!B2="","",'Øhavsskolen Uglen'!B2) -> Øhavsskolerne afd. Uglen | C23: =IF('Øhavsskolen Uglen'!C2="","",'Øhavsskolen Uglen'!C2) -> Bananen | D23: =IF('Øhavsskolen Uglen'!D2="","",'Øhavsskolen Uglen'!D2) -> ve 01 | E23: =IF('Øhavsskolen Uglen'!E2="","",'Øhavsskolen Uglen'!E2) -> Kemp & Lauritzen | F23: =IF('Øhavsskolen Uglen'!F2="","",'Øhavsskolen Uglen'!F2) -> Exhausto VEX3.5-4-1MPR EVR57 | G23: =IF('Øhavsskolen Uglen'!G2="","",'Øhavsskolen Uglen'!G2) -> 2011 | H23: =IF('Øhavsskolen Uglen'!H2="","",'Øhavsskolen Uglen'!H2) -> 1104785 | ... U23: =IF('Øhavsskolen Uglen'!U2="","",'Øhavsskolen Uglen'!U2)
A24: =IF('Øhavsskolen Uglen'!A3="","",'Øhavsskolen Uglen'!A3) -> Toftegårdsvej 7 | B24: =IF('Øhavsskolen Uglen'!B3="","",'Øhavsskolen Uglen'!B3) -> Øhavsskolerne afd. Uglen | C24: =IF('Øhavsskolen Uglen'!C3="","",'Øhavsskolen Uglen'!C3) -> Bananen | D24: =IF('Øhavsskolen Uglen'!D3="","",'Øhavsskolen Uglen'!D3) -> ve 02 | E24: =IF('Øhavsskolen Uglen'!E3="","",'Øhavsskolen Uglen'!E3) -> Kemp & Lauritzen | F24: =IF('Øhavsskolen Uglen'!F3="","",'Øhavsskolen Uglen'!F3) -> Exhausto VEX3.5-4-1MPR EVR57 | G24: =IF('Øhavsskolen Uglen'!G3="","",'Øhavsskolen Uglen'!G3) -> 2011 | H24: =IF('Øhavsskolen Uglen'!H3="","",'Øhavsskolen Uglen'!H3) -> 1104785 | ... U24: =IF('Øhavsskolen Uglen'!U3="","",'Øhavsskolen Uglen'!U3)
A25: =IF('Øhavsskolen Uglen'!A4="","",'Øhavsskolen Uglen'!A4) -> Toftegårdsvej 7 | B25: =IF('Øhavsskolen Uglen'!B4="","",'Øhavsskolen Uglen'!B4) -> Øhavsskolerne afd. Uglen | C25: =IF('Øhavsskolen Uglen'!C4="","",'Øhavsskolen Uglen'!C4) -> Bananen | D25: =IF('Øhavsskolen Uglen'!D4="","",'Øhavsskolen Uglen'!D4) -> ve 03 | E25: =IF('Øhavsskolen Uglen'!E4="","",'Øhavsskolen Uglen'!E4) -> Kemp & Lauritzen | F25: =IF('Øhavsskolen Uglen'!F4="","",'Øhavsskolen Uglen'!F4) -> Exhausto VEX3.5-4-1MPR EVR57 | G25: =IF('Øhavsskolen Uglen'!G4="","",'Øhavsskolen Uglen'!G4) -> 2011 | H25: =IF('Øhavsskolen Uglen'!H4="","",'Øhavsskolen Uglen'!H4) -> 1104785 | ... U25: =IF('Øhavsskolen Uglen'!U4="","",'Øhavsskolen Uglen'!U4)
A26: =IF('Øhavsskolen Uglen'!A5="","",'Øhavsskolen Uglen'!A5) -> Toftegårdsvej 7 | B26: =IF('Øhavsskolen Uglen'!B5="","",'Øhavsskolen Uglen'!B5) -> Øhavsskolerne afd. Uglen | C26: =IF('Øhavsskolen Uglen'!C5="","",'Øhavsskolen Uglen'!C5) -> Bananen | D26: =IF('Øhavsskolen Uglen'!D5="","",'Øhavsskolen Uglen'!D5) -> ve 04 | E26: =IF('Øhavsskolen Uglen'!E5="","",'Øhavsskolen Uglen'!E5) -> Kemp & Lauritzen | F26: =IF('Øhavsskolen Uglen'!F5="","",'Øhavsskolen Uglen'!F5) -> Exhausto VEX3.5-4-1MPR EVR57 | G26: =IF('Øhavsskolen Uglen'!G5="","",'Øhavsskolen Uglen'!G5) -> 2011 | H26: =IF('Øhavsskolen Uglen'!H5="","",'Øhavsskolen Uglen'!H5) -> 1104785 | ... U26: =IF('Øhavsskolen Uglen'!U5="","",'Øhavsskolen Uglen'!U5)
A27: =IF('Øhavsskolen Uglen'!A7="","",'Øhavsskolen Uglen'!A7) -> Toftegårdsvej 7 | B27: =IF('Øhavsskolen Uglen'!B7="","",'Øhavsskolen Uglen'!B7) -> Øhavsskolerne afd. Uglen | C27: =IF('Øhavsskolen Uglen'!C7="","",'Øhavsskolen Uglen'!C7) -> blok 4 | D27: =IF('Øhavsskolen Uglen'!D7="","",'Øhavsskolen Uglen'!D7) -> ve 05 | E27: =IF('Øhavsskolen Uglen'!E7="","",'Øhavsskolen Uglen'!E7) -> NOVENCO | F27: =IF('Øhavsskolen Uglen'!F7="","",'Øhavsskolen Uglen'!F7) -> Climaster ZCF-15 10C-R1 | G27: =IF('Øhavsskolen Uglen'!G7="","",'Øhavsskolen Uglen'!G7) -> 2011 | H27: =IF('Øhavsskolen Uglen'!H7="","",'Øhavsskolen Uglen'!H7) -> 1013468 små | ... U27: =IF('Øhavsskolen Uglen'!U7="","",'Øhavsskolen Uglen'!U7)
A28: =IF('Øhavsskolen Uglen'!A8="","",'Øhavsskolen Uglen'!A8) -> Toftegårdsvej 7 | B28: =IF('Øhavsskolen Uglen'!B8="","",'Øhavsskolen Uglen'!B8) -> Øhavsskolerne afd. Uglen | C28: =IF('Øhavsskolen Uglen'!C8="","",'Øhavsskolen Uglen'!C8) -> blok 4 | D28: =IF('Øhavsskolen Uglen'!D8="","",'Øhavsskolen Uglen'!D8) -> ve 05 | E28: =IF('Øhavsskolen Uglen'!E8="","",'Øhavsskolen Uglen'!E8) -> NOVENCO | F28: =IF('Øhavsskolen Uglen'!F8="","",'Øhavsskolen Uglen'!F8) -> Climaster ZCF-15 10C-R1 | G28: =IF('Øhavsskolen Uglen'!G8="","",'Øhavsskolen Uglen'!G8) -> 2011 | H28: =IF('Øhavsskolen Uglen'!H8="","",'Øhavsskolen Uglen'!H8) -> 1013247 store | ... U28: =IF('Øhavsskolen Uglen'!U8="","",'Øhavsskolen Uglen'!U8)
A29: =IF('Øhavsskolen Uglen'!A9="","",'Øhavsskolen Uglen'!A9) -> Toftegårdsvej 7 | B29: =IF('Øhavsskolen Uglen'!B9="","",'Øhavsskolen Uglen'!B9) -> Øhavsskolerne afd. Uglen | C29: =IF('Øhavsskolen Uglen'!C9="","",'Øhavsskolen Uglen'!C9) -> blok 4 | D29: =IF('Øhavsskolen Uglen'!D9="","",'Øhavsskolen Uglen'!D9) -> ve 05 | E29: =IF('Øhavsskolen Uglen'!E9="","",'Øhavsskolen Uglen'!E9) -> NOVENCO | F29: =IF('Øhavsskolen Uglen'!F9="","",'Øhavsskolen Uglen'!F9) -> Climaster ZCF-15 10C-R1 | G29: =IF('Øhavsskolen Uglen'!G9="","",'Øhavsskolen Uglen'!G9) -> 2011 | H29: =IF('Øhavsskolen Uglen'!H9="","",'Øhavsskolen Uglen'!H9) -> 1013259 stor | ... U29: =IF('Øhavsskolen Uglen'!U9="","",'Øhavsskolen Uglen'!U9)
A30: =IF('Øhavsskolen Uglen'!A10="","",'Øhavsskolen Uglen'!A10) -> Toftegårdsvej 7 | B30: =IF('Øhavsskolen Uglen'!B10="","",'Øhavsskolen Uglen'!B10) -> Øhavsskolerne afd. Uglen | C30: =IF('Øhavsskolen Uglen'!C10="","",'Øhavsskolen Uglen'!C10) -> blok 4 | D30: =IF('Øhavsskolen Uglen'!D10="","",'Øhavsskolen Uglen'!D10) -> ve 05 | E30: =IF('Øhavsskolen Uglen'!E10="","",'Øhavsskolen Uglen'!E10) -> NOVENCO | F30: =IF('Øhavsskolen Uglen'!F10="","",'Øhavsskolen Uglen'!F10) -> Climaster ZCF-15 10C-R1 | G30: =IF('Øhavsskolen Uglen'!G10="","",'Øhavsskolen Uglen'!G10) -> 2011 | H30: =IF('Øhavsskolen Uglen'!H10="","",'Øhavsskolen Uglen'!H10) -> 1013498 Ssmå | ... U30: =IF('Øhavsskolen Uglen'!U10="","",'Øhavsskolen Uglen'!U10)
A31: =IF('Øhavsskolen Uglen'!A12="","",'Øhavsskolen Uglen'!A12) -> Toftegårdsvej 7 | B31: =IF('Øhavsskolen Uglen'!B12="","",'Øhavsskolen Uglen'!B12) -> Øhavsskolerne afd. Uglen | C31: =IF('Øhavsskolen Uglen'!C12="","",'Øhavsskolen Uglen'!C12) -> blok 5 fagblok | D31: =IF('Øhavsskolen Uglen'!D12="","",'Øhavsskolen Uglen'!D12) -> VE01- KØKKEN | E31: =IF('Øhavsskolen Uglen'!E12="","",'Øhavsskolen Uglen'!E12) -> Belvent A/S | F31: =IF('Øhavsskolen Uglen'!F12="","",'Øhavsskolen Uglen'!F12) -> Geniox 10 | G31: =IF('Øhavsskolen Uglen'!G12="","",'Øhavsskolen Uglen'!G12) -> 2024 | H31: =IF('Øhavsskolen Uglen'!H12="","",'Øhavsskolen Uglen'!H12) | ... U31: =IF('Øhavsskolen Uglen'!U12="","",'Øhavsskolen Uglen'!U12)
A32: =IF('Øhavsskolen Uglen'!A13="","",'Øhavsskolen Uglen'!A13) -> Toftegårdsvej 7 | B32: =IF('Øhavsskolen Uglen'!B13="","",'Øhavsskolen Uglen'!B13) -> Øhavsskolerne afd. Uglen | C32: =IF('Øhavsskolen Uglen'!C13="","",'Øhavsskolen Uglen'!C13) -> blok 5 fagblok | D32: =IF('Øhavsskolen Uglen'!D13="","",'Øhavsskolen Uglen'!D13) -> VE01- KØKKEN | E32: =IF('Øhavsskolen Uglen'!E13="","",'Øhavsskolen Uglen'!E13) -> Belvent A/S | F32: =IF('Øhavsskolen Uglen'!F13="","",'Øhavsskolen Uglen'!F13) -> Geniox 10 | G32: =IF('Øhavsskolen Uglen'!G13="","",'Øhavsskolen Uglen'!G13) -> 2024 | H32: =IF('Øhavsskolen Uglen'!H13="","",'Øhavsskolen Uglen'!H13) | ... S32: =IF('Øhavsskolen Uglen'!S13="","",'Øhavsskolen Uglen'!S13)
A33: =IF('Øhavsskolen Uglen'!A16="","",'Øhavsskolen Uglen'!A16) -> Toftegårdsvej 7 | B33: =IF('Øhavsskolen Uglen'!B16="","",'Øhavsskolen Uglen'!B16) -> Øhavsskolerne afd. Uglen | C33: =IF('Øhavsskolen Uglen'!C16="","",'Øhavsskolen Uglen'!C16) -> blok 5 på taget fagblok | D33: =IF('Øhavsskolen Uglen'!D16="","",'Øhavsskolen Uglen'!D16) -> VE02- LOKALER | E33: =IF('Øhavsskolen Uglen'!E16="","",'Øhavsskolen Uglen'!E16) -> Belvent A/S | F33: =IF('Øhavsskolen Uglen'!F16="","",'Øhavsskolen Uglen'!F16) -> Geniox 14 | G33: =IF('Øhavsskolen Uglen'!G16="","",'Øhavsskolen Uglen'!G16) -> 2024 | H33: =IF('Øhavsskolen Uglen'!H16="","",'Øhavsskolen Uglen'!H16) | ... S33: =IF('Øhavsskolen Uglen'!S16="","",'Øhavsskolen Uglen'!S16)
A34: =IF('Øhavsskolen Uglen'!A15="","",'Øhavsskolen Uglen'!A15) -> Toftegårdsvej 7 | B34: =IF('Øhavsskolen Uglen'!B15="","",'Øhavsskolen Uglen'!B15) -> Øhavsskolerne afd. Uglen | C34: =IF('Øhavsskolen Uglen'!C15="","",'Øhavsskolen Uglen'!C15) -> blok 5 på taget fagblok | D34: =IF('Øhavsskolen Uglen'!D15="","",'Øhavsskolen Uglen'!D15) -> VE02- LOKALER | E34: =IF('Øhavsskolen Uglen'!E15="","",'Øhavsskolen Uglen'!E15) -> Belvent A/S | F34: =IF('Øhavsskolen Uglen'!F15="","",'Øhavsskolen Uglen'!F15) -> Geniox 14 | G34: =IF('Øhavsskolen Uglen'!G15="","",'Øhavsskolen Uglen'!G15) -> 2024 | H34: =IF('Øhavsskolen Uglen'!H15="","",'Øhavsskolen Uglen'!H15) | ... S34: =IF('Øhavsskolen Uglen'!S15="","",'Øhavsskolen Uglen'!S15)
A35: =IF('Bøgebjergskolen Vester Åby'!A2="","",'Bøgebjergskolen Vester Åby'!A2) -> Svendborgvej 357 | B35: =IF('Bøgebjergskolen Vester Åby'!B2="","",'Bøgebjergskolen Vester Åby'!B2) -> Bøgebjergskolen | C35: =IF('Bøgebjergskolen Vester Åby'!C2="","",'Bøgebjergskolen Vester Åby'!C2) -> Børnehaven loft over fyrrum | D35: =IF('Bøgebjergskolen Vester Åby'!D2="","",'Bøgebjergskolen Vester Åby'!D2) | E35: =IF('Bøgebjergskolen Vester Åby'!E2="","",'Bøgebjergskolen Vester Åby'!E2) | F35: =IF('Bøgebjergskolen Vester Åby'!F2="","",'Bøgebjergskolen Vester Åby'!F2) -> WR EKOSALDA RIS 2500 H | G35: =IF('Bøgebjergskolen Vester Åby'!G2="","",'Bøgebjergskolen Vester Åby'!G2) -> 2015 | H35: =IF('Bøgebjergskolen Vester Åby'!H2="","",'Bøgebjergskolen Vester Åby'!H2) -> 1007426 | ... U35: =IF('Bøgebjergskolen Vester Åby'!U2="","",'Bøgebjergskolen Vester Åby'!U2)
A36: =IF('Bøgebjergskolen Vester Åby'!A3="","",'Bøgebjergskolen Vester Åby'!A3) -> Svendborgvej 357 | B36: =IF('Bøgebjergskolen Vester Åby'!B3="","",'Bøgebjergskolen Vester Åby'!B3) -> Bøgebjergskolen | C36: =IF('Bøgebjergskolen Vester Åby'!C3="","",'Bøgebjergskolen Vester Åby'!C3) -> Børnehaven loft over fyrrum | D36: =IF('Bøgebjergskolen Vester Åby'!D3="","",'Bøgebjergskolen Vester Åby'!D3) | E36: =IF('Bøgebjergskolen Vester Åby'!E3="","",'Bøgebjergskolen Vester Åby'!E3) | F36: =IF('Bøgebjergskolen Vester Åby'!F3="","",'Bøgebjergskolen Vester Åby'!F3) -> WR EKOSALDA RIS 2500 H | G36: =IF('Bøgebjergskolen Vester Åby'!G3="","",'Bøgebjergskolen Vester Åby'!G3) -> 2015 | H36: =IF('Bøgebjergskolen Vester Åby'!H3="","",'Bøgebjergskolen Vester Åby'!H3) -> 1007368 | ... U36: =IF('Bøgebjergskolen Vester Åby'!U3="","",'Bøgebjergskolen Vester Åby'!U3)
A37: =IF('Bøgebjergskolen Vester Åby'!A5="","",'Bøgebjergskolen Vester Åby'!A5) -> Svendborgvej 357 | B37: =IF('Bøgebjergskolen Vester Åby'!B5="","",'Bøgebjergskolen Vester Åby'!B5) -> Bøgebjergskolen | C37: =IF('Bøgebjergskolen Vester Åby'!C5="","",'Bøgebjergskolen Vester Åby'!C5) -> Skolen kælder ved gymnastik | D37: =IF('Bøgebjergskolen Vester Åby'!D5="","",'Bøgebjergskolen Vester Åby'!D5) -> VEN 01 | E37: =IF('Bøgebjergskolen Vester Åby'!E5="","",'Bøgebjergskolen Vester Åby'!E5) | F37: =IF('Bøgebjergskolen Vester Åby'!F5="","",'Bøgebjergskolen Vester Åby'!F5) -> Komfovent Verso-R-3000-V-W | G37: =IF('Bøgebjergskolen Vester Åby'!G5="","",'Bøgebjergskolen Vester Åby'!G5) | H37: =IF('Bøgebjergskolen Vester Åby'!H5="","",'Bøgebjergskolen Vester Åby'!H5) -> Der er inne noget nr. | ... K37: =IF('Bøgebjergskolen Vester Åby'!K5="","",'Bøgebjergskolen Vester Åby'!K5) -> 525x510x48 | L37: =IF('Bøgebjergskolen Vester Åby'!#REF!="","",'Bøgebjergskolen Vester Åby'!#REF!) -> #REF! | M37: =IF('Bøgebjergskolen Vester Åby'!M5="","",'Bøgebjergskolen Vester Åby'!M5) -> Ja | N37: =IF('Bøgebjergskolen Vester Åby'!N5="","",'Bøgebjergskolen Vester Åby'!N5) | O37: =IF('Bøgebjergskolen Vester Åby'!O5="","",'Bøgebjergskolen Vester Åby'!O5) -> 45968 | P37: =IF('Bøgebjergskolen Vester Åby'!P5="","",'Bøgebjergskolen Vester Åby'!P5) -> -69 | Q37: =IF('Bøgebjergskolen Vester Åby'!Q5="","",'Bøgebjergskolen Vester Åby'!Q5) -> Kjeld / Ian | R37: =IF('Bøgebjergskolen Vester Åby'!R5="","",'Bøgebjergskolen Vester Åby'!R5) -> 45777 | S37: =IF('Bøgebjergskolen Vester Åby'!L5="","",'Bøgebjergskolen Vester Åby'!L5) -> CTS | T37: =IF('Bøgebjergskolen Vester Åby'!T5="","",'Bøgebjergskolen Vester Åby'!T5) | U37: =IF('Bøgebjergskolen Vester Åby'!U5="","",'Bøgebjergskolen Vester Åby'!U5)
A38: =IF('Bøgebjergskolen Vester Åby'!A6="","",'Bøgebjergskolen Vester Åby'!A6) -> Svendborgvej 357 | B38: =IF('Bøgebjergskolen Vester Åby'!B6="","",'Bøgebjergskolen Vester Åby'!B6) -> Bøgebjergskolen | C38: =IF('Bøgebjergskolen Vester Åby'!C6="","",'Bøgebjergskolen Vester Åby'!C6) -> Skolen kælder ved gymnastik | D38: =IF('Bøgebjergskolen Vester Åby'!D6="","",'Bøgebjergskolen Vester Åby'!D6) | E38: =IF('Bøgebjergskolen Vester Åby'!E6="","",'Bøgebjergskolen Vester Åby'!E6) | F38: =IF('Bøgebjergskolen Vester Åby'!F6="","",'Bøgebjergskolen Vester Åby'!F6) -> Komfovent Verso-R-3000-V-W | G38: =IF('Bøgebjergskolen Vester Åby'!G6="","",'Bøgebjergskolen Vester Åby'!G6) | H38: =IF('Bøgebjergskolen Vester Åby'!H6="","",'Bøgebjergskolen Vester Åby'!H6) -> Der er inne noget nr. | ... K38: =IF('Bøgebjergskolen Vester Åby'!K6="","",'Bøgebjergskolen Vester Åby'!K6) -> 525X510X48 | L38: =IF('Bøgebjergskolen Vester Åby'!#REF!="","",'Bøgebjergskolen Vester Åby'!#REF!) -> #REF! | M38: =IF('Bøgebjergskolen Vester Åby'!M6="","",'Bøgebjergskolen Vester Åby'!M6) -> Ja | N38: =IF('Bøgebjergskolen Vester Åby'!N6="","",'Bøgebjergskolen Vester Åby'!N6) | O38: =IF('Bøgebjergskolen Vester Åby'!O6="","",'Bøgebjergskolen Vester Åby'!O6) -> 45968 | P38: =IF('Bøgebjergskolen Vester Åby'!P6="","",'Bøgebjergskolen Vester Åby'!P6) -> -69 | Q38: =IF('Bøgebjergskolen Vester Åby'!Q6="","",'Bøgebjergskolen Vester Åby'!Q6) -> Kjeld / Ian | R38: =IF('Bøgebjergskolen Vester Åby'!R6="","",'Bøgebjergskolen Vester Åby'!R6) -> 45777 | S38: =IF('Bøgebjergskolen Vester Åby'!L6="","",'Bøgebjergskolen Vester Åby'!L6) -> CTS | T38: =IF('Bøgebjergskolen Vester Åby'!T6="","",'Bøgebjergskolen Vester Åby'!T6) | U38: =IF('Bøgebjergskolen Vester Åby'!U6="","",'Bøgebjergskolen Vester Åby'!U6)
A39: =IF('Bøgebjergskolen Vester Åby'!A9="","",'Bøgebjergskolen Vester Åby'!A9) -> Svendborgvej 357 | B39: =IF('Bøgebjergskolen Vester Åby'!B9="","",'Bøgebjergskolen Vester Åby'!B9) -> Bøgebjergskolen | C39: =IF('Bøgebjergskolen Vester Åby'!C9="","",'Bøgebjergskolen Vester Åby'!C9) -> Skolen loft over kontor | D39: =IF('Bøgebjergskolen Vester Åby'!D9="","",'Bøgebjergskolen Vester Åby'!D9) | E39: =IF('Bøgebjergskolen Vester Åby'!E9="","",'Bøgebjergskolen Vester Åby'!E9) | F39: =IF('Bøgebjergskolen Vester Åby'!F9="","",'Bøgebjergskolen Vester Åby'!F9) -> Komfovent Verso-R-20-ML | G39: =IF('Bøgebjergskolen Vester Åby'!G9="","",'Bøgebjergskolen Vester Åby'!G9) | H39: =IF('Bøgebjergskolen Vester Åby'!H9="","",'Bøgebjergskolen Vester Åby'!H9) -> Der er ikke noget nr. | ... K39: =IF('Bøgebjergskolen Vester Åby'!K9="","",'Bøgebjergskolen Vester Åby'!K9) -> 490x490x500 | L39: =IF('Bøgebjergskolen Vester Åby'!#REF!="","",'Bøgebjergskolen Vester Åby'!#REF!) -> #REF! | M39: =IF('Bøgebjergskolen Vester Åby'!M9="","",'Bøgebjergskolen Vester Åby'!M9) -> Ja | N39: =IF('Bøgebjergskolen Vester Åby'!N9="","",'Bøgebjergskolen Vester Åby'!N9) | O39: =IF('Bøgebjergskolen Vester Åby'!O9="","",'Bøgebjergskolen Vester Åby'!O9) -> 45968 | P39: =IF('Bøgebjergskolen Vester Åby'!P9="","",'Bøgebjergskolen Vester Åby'!P9) -> -69 | Q39: =IF('Bøgebjergskolen Vester Åby'!Q9="","",'Bøgebjergskolen Vester Åby'!Q9) -> Kjeld / Ian | R39: =IF('Bøgebjergskolen Vester Åby'!R9="","",'Bøgebjergskolen Vester Åby'!R9) -> 45777 | S39: =IF('Bøgebjergskolen Vester Åby'!L9="","",'Bøgebjergskolen Vester Åby'!L9) -> CTS | T39: =IF('Bøgebjergskolen Vester Åby'!T9="","",'Bøgebjergskolen Vester Åby'!T9) | U39: =IF('Bøgebjergskolen Vester Åby'!U9="","",'Bøgebjergskolen Vester Åby'!U9)
A40: =IF('Bøgebjergskolen Vester Åby'!A12="","",'Bøgebjergskolen Vester Åby'!A12) -> Svendborgvej 357 | B40: =IF('Bøgebjergskolen Vester Åby'!B12="","",'Bøgebjergskolen Vester Åby'!B12) -> Bøgebjergskolen | C40: =IF('Bøgebjergskolen Vester Åby'!C12="","",'Bøgebjergskolen Vester Åby'!C12) -> Skolen ved Billedkunst | D40: =IF('Bøgebjergskolen Vester Åby'!D12="","",'Bøgebjergskolen Vester Åby'!D12) | E40: =IF('Bøgebjergskolen Vester Åby'!E12="","",'Bøgebjergskolen Vester Åby'!E12) | F40: =IF('Bøgebjergskolen Vester Åby'!F12="","",'Bøgebjergskolen Vester Åby'!F12) -> Komfovent Verso | G40: =IF('Bøgebjergskolen Vester Åby'!G12="","",'Bøgebjergskolen Vester Åby'!G12) | H40: =IF('Bøgebjergskolen Vester Åby'!H12="","",'Bøgebjergskolen Vester Åby'!H12) -> Der er ikke noget nr. | ... K40: =IF('Bøgebjergskolen Vester Åby'!K12="","",'Bøgebjergskolen Vester Åby'!K12) -> 525x510x48 | L40: =IF('Bøgebjergskolen Vester Åby'!#REF!="","",'Bøgebjergskolen Vester Åby'!#REF!) -> #REF! | M40: =IF('Bøgebjergskolen Vester Åby'!M12="","",'Bøgebjergskolen Vester Åby'!M12) -> er el | N40: =IF('Bøgebjergskolen Vester Åby'!N12="","",'Bøgebjergskolen Vester Åby'!N12) | O40: =IF('Bøgebjergskolen Vester Åby'!O12="","",'Bøgebjergskolen Vester Åby'!O12) -> 45968 | P40: =IF('Bøgebjergskolen Vester Åby'!P12="","",'Bøgebjergskolen Vester Åby'!P12) -> -69 | Q40: =IF('Bøgebjergskolen Vester Åby'!Q12="","",'Bøgebjergskolen Vester Åby'!Q12) -> Kjeld / Ian | R40: =IF('Bøgebjergskolen Vester Åby'!R12="","",'Bøgebjergskolen Vester Åby'!R12) -> 45777 | S40: =IF('Bøgebjergskolen Vester Åby'!L12="","",'Bøgebjergskolen Vester Åby'!L12) -> CTS | T40: =IF('Bøgebjergskolen Vester Åby'!T12="","",'Bøgebjergskolen Vester Åby'!T12) | U40: =IF('Bøgebjergskolen Vester Åby'!U12="","",'Bøgebjergskolen Vester Åby'!U12)
...

Sheet Forside
A1: Ejendomme | B1: Team
A2: allested-vejle skole
A3: BH Damtoften
A4: bh oasen | B4: Team 3
A5: brahetrolleborg/heldagsskolen | B5: Team 1
A6: Broholm Børnehave
A7: broskolen bøgehøj
A8: byskolen | B8: Team 1
A9: børnehaven kahytten
A10: Carl Nielsen Børnehuset | B10: TEAM 6
A11: Carl Nielsen skolen | B11: TEAM 6
A12: den blå ambassadør
A13: espe skole
A14: Faaborg Bibliotek
A15: Faaborg Tandpleje | B15: Team 1
A16: CAI | B16: Team 3
A17: Guldhøj
A18: Horne skole
A19: Hættegården
A20: it huset | B20: Team 3
A21: Jobcentret | B21: Team 7
A22: kernehuset | B22: Team 3
A23: kulturhuset
A24: lundsbjerg børnehave
A25: motorikken/klatretræet
A26: Musik skolen Ringe
A27: Myretuen
A28: nordagerskolen
A29: Nr. broby. Gl. Rådhus
A30: nøddehøj | B30: Team 5
A31: Palleshave
A32: Pontoppidan skolen
A33: ringe tandklinik
A34: rolfsted skole
A35: rådhus fåborg
A36: rådhus ringe
A37: solen svanninge vuggestue
A38: solstrålen
A39: stu /hj.plejen broby
A40: Sundbrinken | B40: Team 1
...

Sheet Bøgebjergskolen Vester Åby
A1: Adresse | B1: Navn | C1: Placering på anlæg | D1: Anlægsnr. | E1: Leverandør | F1: Type | G1: Årstal for opsætning | H1: Gammel filter nr | I1: Nyt filter nr | J1: Antal filtre | K1: Str på filter | L1: Styring | M1: Frostsikring | N1: Luftmængde (Vent-ordning) | O1: Dato for filterskifte | P1: Dage siden skift | Q1: Person som har skiftet filtret | R1: Dato på eftersyn (VENT-ordning) | S1: Kommentar. / Anmærkninger | T1: Service | U1: Hvornår udløber kontrakt
A2: Svendborgvej 357 | B2: Bøgebjergskolen | C2: Børnehaven loft over fyrrum | F2: WR EKOSALDA RIS 2500 H | G2: 2015 | H2: 1007426 | I2: 1007426 | J2: 1 | K2: 79x525x90 | L2: På anlæg | M2: Ja | O2: 45798 | P2: =IF(AND(A2="",B2="",C2=""),"",IF(O2="",-1000,(O2-TODAY()))) -> -239 | Q2: Per storm | V2: Vi har filter som står i fyrrumet i børnehaven
A3: Svendborgvej 357 | B3: Bøgebjergskolen | C3: Børnehaven loft over fyrrum | F3: WR EKOSALDA RIS 2500 H | G3: 2015 | H3: 1007368 | I3: 1007368 | J3: 1 | K3: 79x525x90 | L3: På anlæg | M3: Ja | O3: 45798 | P3: =IF(AND(A3="",B3="",C3=""),"",IF(O3="",-1000,(O3-TODAY()))) -> -239 | Q3: Per storm | V3: Vi har filter som står i fyrrumet i børnehaven
P4: =IF(AND(A4="",B4="",C4=""),"",IF(O4="",-1000,(O4-TODAY())))
A5: Svendborgvej 357 | B5: Bøgebjergskolen | C5: Skolen kælder ved gymnastik | D5: VEN 01 | F5: Komfovent Verso-R-3000-V-W | H5: Der er inne noget nr. | I5: 525x510x48 | J5: 2 | K5: 525x510x48 | L5: CTS | M5: Ja | O5: 45968 | P5: =IF(AND(A5="",B5="",C5=""),"",IF(O5="",-1000,(O5-TODAY()))) -> -69 | Q5: Kjeld / Ian | R5: 45777
A6: Svendborgvej 357 | B6: Bøgebjergskolen | C6: Skolen kælder ved gymnastik | F6: Komfovent Verso-R-3000-V-W | H6: Der er inne noget nr. | I6: 525x510x48 | J6: 2 | K6: 525X510X48 | L6: CTS | M6: Ja | O6: 45968 | P6: =IF(AND(A6="",B6="",C6=""),"",IF(O6="",-1000,(O6-TODAY()))) -> -69 | Q6: Kjeld / Ian | R6: 45777
P7: =IF(AND(A7="",B7="",C7=""),"",IF(O7="",-1000,(O7-TODAY())))
A8: Svendborgvej 357 | B8: Bøgebjergskolen | C8: Skolen loft over kontor | D8: VEN 02 | F8: Komfovent Verso-R-20-ML | H8: Der er ikke noget nr. | I8: 490x490x500 | J8: 2 | K8: 490x490x500 | L8: CTS | M8: Ja | O8: 45968 | P8: =IF(AND(A8="",B8="",C8=""),"",IF(O8="",-1000,(O8-TODAY()))) -> -69 | Q8: Kjeld / Ian | R8: 45777
A9: Svendborgvej 357 | B9: Bøgebjergskolen | C9: Skolen loft over kontor | F9: Komfovent Verso-R-20-ML | H9: Der er ikke noget nr. | I9: 490x490x500 | J9: 2 | K9: 490x490x500 | L9: CTS | M9: Ja | O9: 45968 | P9: =IF(AND(A9="",B9="",C9=""),"",IF(O9="",-1000,(O9-TODAY()))) -> -69 | Q9: Kjeld / Ian | R9: 45777
P10: =IF(AND(A10="",B10="",C10=""),"",IF(O10="",-1000,(O10-TODAY())))
A11: Svendborgvej 357 | B11: Bøgebjergskolen | C11: Skolen ved Billedkunst | D11: VEN 03 | F11: Komfovent Verso | H11: Der er inne noget nr. | I11: 525x510x48 | J11: 2 | K11: 525x510x48 | L11: CTS | M11: Varme flade | O11: 45968 | P11: =IF(AND(A11="",B11="",C11=""),"",IF(O11="",-1000,(O11-TODAY()))) -> -69 | Q11: Kjeld / Ian | R11: 45777
A12: Svendborgvej 357 | B12: Bøgebjergskolen | C12: Skolen ved Billedkunst | F12: Komfovent Verso | H12: Der er ikke noget nr. | I12: 525x510x48 | J12: 2 | K12: 525x510x48 | L12: CTS | M12: er el | O12: 45968 | P12: =IF(AND(A12="",B12="",C12=""),"",IF(O12="",-1000,(O12-TODAY()))) -> -69 | Q12: Kjeld / Ian | R12: 45777
P13: =IF(AND(A13="",B13="",C13=""),"",IF(O13="",-1000,(O13-TODAY())))
P14: =IF(AND(A14="",B14="",C14=""),"",IF(O14="",-1000,(O14-TODAY())))
P15: =IF(AND(A15="",B15="",C15=""),"",IF(O15="",-1000,(O15-TODAY())))
P16: =IF(AND(A16="",B16="",C16=""),"",IF(O16="",-1000,(O16-TODAY())))
P17: =IF(AND(A17="",B17="",C17=""),"",IF(O17="",-1000,(O17-TODAY())))
P18: =IF(AND(A18="",B18="",C18=""),"",IF(O18="",-1000,(O18-TODAY())))
P19: =IF(AND(A19="",B19="",C19=""),"",IF(O19="",-1000,(O19-TODAY())))
P20: =IF(AND(A20="",B20="",C20=""),"",IF(O20="",-1000,(O20-TODAY())))
P21: =IF(AND(A21="",B21="",C21=""),"",IF(O21="",-1000,(O21-TODAY())))
P22: =IF(AND(A22="",B22="",C22=""),"",IF(O22="",-1000,(O22-TODAY())))
P23: =IF(AND(A23="",B23="",C23=""),"",IF(O23="",-1000,(O23-TODAY())))
P24: =IF(AND(A24="",B24="",C24=""),"",IF(O24="",-1000,(O24-TODAY())))
... P61: =IF(AND(A61="",B61="",C61=""),"",IF(O61="",-1000,(O61-TODAY())))

Sheet BYSKOLEN
A1: Adresse | B1: Navn | C1: Placering på anlæg | D1: Anlægsnr. | E1: Leverandør | F1: Type | G1: Årstal for opsætning | H1: Gammel filter nr | I1: Nyt filter nr | J1: Antal filtre | K1: Str på filter | L1: Styring | M1: Frostsikring | N1: Luftmængde (Vent-ordning) | O1: Dato for filterskifte | P1: Dage siden skift | Q1: Person som har skiftet filtret | R1: Dato på eftersyn (VENT-ordning) | S1: Kommentar. / Anmærkninger | T1: Service | U1: Hvornår udløber kontrakt | V1: Har vi filter til næste skift
P2: =IF(AND(A2="",B2="",C2=""),"",IF(O2="",-1000,(O2-TODAY())))
A3: Grønnegade 40-44 | B3: Byskolen | C3: ungdomsskolen i stuen | F3: EXHAUSTO V260 | G3: 2015 | H3: 1013419 / 612811 | I3: 1013419 / 612811 | J3: 1 | K3: 592x592x370 | L3: På anlæg | M3: isoleretrum | O3: 45979 | P3: =IF(AND(A3="",B3="",C3=""),"",IF(O3="",-1000,(O3-TODAY()))) -> -58 | Q3: Kjeld / Per | S3: ind | T3: Nej
A4: Grønnegade 40-44 | B4: Byskolen | C4: ungdomsskolen i stuen | F4: EXHAUSTO V260 | G4: 2015 | H4: 1013473 / 612821 | I4: 1013473 / 612821 | J4: 1 | K4: 490x592x370 | L4: På anlæg | M4: isoleretrum | O4: 45979 | P4: =IF(AND(A4="",B4="",C4=""),"",IF(O4="",-1000,(O4-TODAY()))) -> -58 | Q4: Kjeld / Per | S4: ind | T4: Nej
A5: Grønnegade 40-44 | B5: Byskolen | C5: ungdomsskolen i stuen | F5: EXHAUSTO V260 | G5: 2015 | H5: 1013443 / 612815 | I5: 1013443 / 612815 | J5: 1 | K5: 592x592x370 | L5: På anlæg | M5: isoleretrum | O5: 45979 | P5: =IF(AND(A5="",B5="",C5=""),"",IF(O5="",-1000,(O5-TODAY()))) -> -58 | Q5: Kjeld / Per | S5: ud | T5: Nej
A6: Grønnegade 40-44 | B6: Byskolen | C6: ungdomsskolen i stuen | F6: EXHAUSTO V260 | G6: 2015 | H6: 1013503 / 612827 | I6: 1013503 / 612827 | J6: 1 | K6: 490x592x370 | L6: På anlæg | M6: isoleretrum | O6: 45979 | P6: =IF(AND(A6="",B6="",C6=""),"",IF(O6="",-1000,(O6-TODAY()))) -> -58 | Q6: Kjeld / Per | S6: ud | T6: Nej
P7: =IF(AND(A7="",B7="",C7=""),"",IF(O7="",-1000,(O7-TODAY())))
A8: Grønnegade 40-44 | B8: Byskolen | C8: gymnastik 1. sal | F8: Topvex TR04 HWH-L-VAV | G8: ? | H8: 1016229 / 621387 | I8: 1016229 / 621387 | J8: 1 | K8: 340x753x300 | L8: På anlæf | M8: isoleretrum | O8: 45889 | P8: =IF(AND(A8="",B8="",C8=""),"",IF(O8="",-1000,(O8-TODAY()))) -> -148 | Q8: Kjeld / Per | S8: ind | T8: Nej
A9: Grønnegade 40-44 | B9: Byskolen | C9: gymnastik 1. sal | F9: Topvex TR04 HWH-L-VAV | G9: ? | H9: 1009056 / 608231 | I9: 1009056 / 608231 | J9: 1 | K9: 320x753x300 | L9: på anlæg | M9: isoleretrum | O9: 45889 | P9: =IF(AND(A9="",B9="",C9=""),"",IF(O9="",-1000,(O9-TODAY()))) -> -148 | Q9: Kjeld / Per | S9: ud | T9: Nej
P10: =IF(AND(A10="",B10="",C10=""),"",IF(O10="",-1000,(O10-TODAY())))
P12: =IF(AND(A12="",B12="",C12=""),"",IF(O12="",-1000,(O12-TODAY())))
P13: =IF(AND(A13="",B13="",C13=""),"",IF(O13="",-1000,(O13-TODAY())))
P14: =IF(AND(A14="",B14="",C14=""),"",IF(O14="",-1000,(O14-TODAY())))
P15: =IF(AND(A15="",B15="",C15=""),"",IF(O15="",-1000,(O15-TODAY())))
P16: =IF(AND(A16="",B16="",C16=""),"",IF(O16="",-1000,(O16-TODAY())))
P17: =IF(AND(A17="",B17="",C17=""),"",IF(O17="",-1000,(O17-TODAY())))
P18: =IF(AND(A18="",B18="",C18=""),"",IF(O18="",-1000,(O18-TODAY())))
P19: =IF(AND(A19="",B19="",C19=""),"",IF(O19="",-1000,(O19-TODAY())))
P20: =IF(AND(A20="",B20="",C20=""),"",IF(O20="",-1000,(O20-TODAY())))
P21: =IF(AND(A21="",B21="",C21=""),"",IF(O21="",-1000,(O21-TODAY())))
P22: =IF(AND(A22="",B22="",C22=""),"",IF(O22="",-1000,(O22-TODAY())))
... P72: =IF(AND(A72="",B72="",C72=""),"",IF(O72="",-1000,(O72-TODAY())))
P73: =IF(AND(A73="",B73="",C73=""),"",IF(O73="",1000,(O73-TODAY())))
P74: =IF(AND(A74="",B74="",C74=""),"",IF(O74="",1000,(O74-TODAY())))
P75: =IF(AND(A75="",B75="",C75=""),"",IF(O75="",1000,(O75-TODAY())))
P76: =IF(AND(A76="",B76="",C76=""),"",IF(O76="",1000,(O76-TODAY())))
P77: =IF(AND(A77="",B77="",C77=""),"",IF(O77="",1000,(O77-TODAY())))
P78: =IF(AND(A78="",B78="",C78=""),"",IF(O78="",1000,(O78-TODAY())))
P79: =IF(AND(A79="",B79="",C79=""),"",IF(O79="",1000,(O79-TODAY())))
P80: =IF(AND(A80="",B80="",C80=""),"",IF(O80="",1000,(O80-TODAY())))
P81: =IF(AND(A81="",B81="",C81=""),"",IF(O81="",1000,(O81-TODAY())))
P82: =IF(AND(A82="",B82="",C82=""),"",IF(O82="",1000,(O82-TODAY())))
P83: =IF(AND(A83="",B83="",C83=""),"",IF(O83="",1000,(O83-TODAY())))
P84: =IF(AND(A84="",B84="",C84=""),"",IF(O84="",1000,(O84-TODAY())))
... P142: =IF(AND(A142="",B142="",C142=""),"",IF(O142="",1000,(O142-TODAY())))

Sheet brahetrolleborg-heldagsskolen
A1: Adresse | B1: Navn | C1: Placering på anlæg | D1: Anlægsnr. | E1: Leverandør | F1: Type | G1: Årstal for opsætning | H1: Gammel filter nr | I1: Nyt filter nr | J1: Antal filtre | K1: Str på filter | L1: Styring | M1: Frostsikring | N1: Luftmængde (Vent-ordning) | O1: Dato for filterskifte | P1: Dage siden skift | Q1: Person som har skiftet filtret | R1: Dato på eftersyn (VENT-ordning) | S1: Kommentar. / Anmærkninger | T1: Service | U1: Hvornår udløber kontrakt
A2: Reventlowsvej 26 | B2: Heldagsskolen | C2: Køkken | H2: 1007117 | I2: 1007117 | J2: 2 | M2: nej | O2: 45173 | P2: =IF(AND(A2="",B2="",C2=""),"",IF(O2="",-1000,(O2-TODAY()))) -> -864
A4: Reventlowsvej 26 | B4: Heldagsskolen | C4: Overbygning | F4: AM500h | H4: 222151 | J4: 2 | M4: nej | O4: 45237 | P4: =IF(AND(A4="",B4="",C4=""),"",IF(O4="",-1000,(O4-TODAY()))) -> -800
A5: Reventlowsvej 26 | B5: Heldagsskolen | C5: Overbygning | F5: AM500h | H5: 222152 | J5: 2 | M5: nej | O5: 45237 | P5: =IF(AND(A5="",B5="",C5=""),"",IF(O5="",-1000,(O5-TODAY()))) -> -800
A7: Reventlowsvej 26 | B7: Heldagsskolen | C7: Fysik | F7: vex3 | H7: 23454402 | I7: 1104785 | J7: 1 | M7: nej | O7: 45173 | P7: =IF(AND(A7="",B7="",C7=""),"",IF(O7="",-1000,(O7-TODAY()))) -> -864
A8: Reventlowsvej 26 | B8: Heldagsskolen | C8: Fysik | F8: vex3 | H8: 23474403 | I8: 1104743 | J8: 1 | M8: nej | O8: 45173 | P8: =IF(AND(A8="",B8="",C8=""),"",IF(O8="",-1000,(O8-TODAY()))) -> -864
A10: Reventlowsvej 26 | B10: Heldagsskolen | C10: sfo | F10: vex150 | H10: 23557502 | I10: 1104755 | J10: 1 | M10: nej | O10: 45173 | P10: =IF(AND(A10="",B10="",C10=""),"",IF(O10="",-1000,(O10-TODAY()))) -> -864
A11: Reventlowsvej 26 | B11: Heldagsskolen | C11: sfo | F11: vex150 | H11: 23577500 | I11: 1104851 | J11: 1 | M11: nej | O11: 45173 | P11: =IF(AND(A11="",B11="",C11=""),"",IF(O11="",-1000,(O11-TODAY()))) -> -864
A13: Reventlowsvej 26 | B13: Heldagsskolen | C13: vestfløj | F13: Geniox 18 | H13: 1013815 | I13: 1013815 | J13: 6 | M13: ja | O13: 45190 | P13: =IF(AND(A13="",B13="",C13=""),"",IF(O13="",-1000,(O13-TODAY()))) -> -847
A14: Reventlowsvej 26 | B14: Heldagsskolen | C14: vestfløj | F14: Geniox 18 | H14: 1013840 | I14: 1013840 | J14: 6 | M14: ja | O14: 45190 | P14: =IF(AND(A14="",B14="",C14=""),"",IF(O14="",-1000,(O14-TODAY()))) -> -847
P15: =IF(AND(A15="",B15="",C15=""),"",IF(O15="",-1000,(O15-TODAY())))
P16: =IF(AND(A16="",B16="",C16=""),"",IF(O16="",-1000,(O16-TODAY())))

Sheet Øhavsskolen Svanen 
A1: Adresse | B1: Navn | C1: Placering på anlæg | D1: Anlægsnr. | E1: Leverandør | F1: Type | G1: Årstal for opsætning | H1: Gammel filter nr | I1: Nyt filter nr | J1: Antal filtre | K1: Str på filter | L1: Styring | M1: Frostsikring | N1: Luftmængde (Vent-ordning) | O1: Dato for filterskifte | P1: Dage siden skift | Q1: Person som har skiftet filtret | R1: Dato på eftersyn (VENT-ordning) | S1: Kommentar. / Anmærkninger | T1: Service | U1: Hvornår udløber kontrakt | V1: Har vi filter til næste skift
A2: Sundvænget 9 | B2: Øhavsskolen Svanen | C2: byg c loft | D2: ve01 | H2: 1013259 | I2: 1013259 | J2: 4 | K2: 592x592x520 | M2: nej | O2: 45910 | P2: =IF(AND(A2="",B2="",C2=""),"",IF(O2="",-1000,(O2-TODAY()))) -> -127 | Q2: jens/per | S2: admin 40 til 43 | T2: ikke bestil før 27
A3: Sundvænget 9 | B3: Øhavsskolen Svanen | C3: byg c loft | D3: ve01 | H3: 1013128 | I3: 1013128 | J3: 2 | K3: 287x592x520 | M3: nej | O3: 45910 | P3: =IF(AND(A3="",B3="",C3=""),"",IF(O3="",-1000,(O3-TODAY()))) -> -127 | Q3: jens/per | S3: admin 40 til 43 | T3: ikke bestil før 27 | W3: Billeder\SVANEN\BLOK C GAMMEL
A5: Sundvænget 9 | B5: Øhavsskolen Svanen | C5: byg c 1 sal | D5: ve02 | H5: 1013259 | I5: 1013259 | J5: 2 | K5: 592x592x520 | M5: nej | O5: 45910 | P5: =IF(AND(A5="",B5="",C5=""),"",IF(O5="",-1000,(O5-TODAY()))) -> -127 | Q5: jens/per
A6: Sundvænget 9 | B6: Øhavsskolen Svanen | C6: byg c 1 sal | D6: ve02 | H6: 1013498 | I6: 1013498 | J6: 2 | K6: 490x592x520 | M6: nej | O6: 45910 | P6: =IF(AND(A6="",B6="",C6=""),"",IF(O6="",-1000,(O6-TODAY()))) -> -127 | Q6: jens/per | W6: Billeder\SVANEN\BLOK C 1 SAL NY
A7: Sundvænget 9 | B7: Øhavsskolen Svanen | C7: byg c 1 sal | D7: ve02 | H7: 1013128 | I7: 1013128 | J7: 2 | K7: 287x592x520 | M7: nej | O7: 45910 | P7: =IF(AND(A7="",B7="",C7=""),"",IF(O7="",-1000,(O7-TODAY()))) -> -127 | Q7: jens/per
A9: Sundvænget 9 | B9: Øhavsskolen Svanen | C9: på taget over aula | D9: ve03 | H9: 1013259 | I9: 1013259 | J9: 2 kasser 4 | K9: 592X592X520 | M9: nej | O9: 45727 | P9: =IF(AND(A9="",B9="",C9=""),"",IF(O9="",-1000,(O9-TODAY()))) -> -310 | Q9: Jens/Kjeld | S9: ej genbestilles før 27 | W9: Billeder\SVANEN\TAG VE 03
A10: Sundvænget 9 | B10: Øhavsskolen Svanen | C10: på taget over aula | D10: ve03 | H10: 1013128 | I10: 1013128 | J10: 2 | K10: 287X592X520 | M10: nej | O10: 45727 | P10: =IF(AND(A10="",B10="",C10=""),"",IF(O10="",-1000,(O10-TODAY()))) -> -310 | Q10: Jens/Kjeld | S10: ej genbestille før 27
P11: =IF(AND(A11="",B11="",C11=""),"",IF(O11="",-1000,(O11-TODAY())))
A12: Sundvænget 9 | B12: Øhavsskolen Svanen | C12: byg a loft | D12: ve04 | H12: 1013259 | I12: 1013259 | J12: 2 kasser 4 | K12: 592x592x520 | M12: nej | O12: 45910 | P12: =IF(AND(A12="",B12="",C12=""),"",IF(O12="",-1000,(O12-TODAY()))) -> -127 | Q12: jens/per | S12: admin 40 til 43 | W12: Billeder\SVANEN\BLOK A 1 SAL GAMMEL
A13: Sundvænget 9 | B13: Øhavsskolen Svanen | C13: byg a loft | D13: ve04 | H13: 1013128 | I13: 1013128 | J13: 2 | K13: 287x592x520 | M13: nej | O13: 45910 | P13: =IF(AND(A13="",B13="",C13=""),"",IF(O13="",-1000,(O13-TODAY()))) -> -127 | Q13: jens/per | S13: admin 40 til 43
A14: Sundvænget 9 | B14: Øhavsskolen Svanen | C14: byg b loft | D14: ve05 | H14: 1013259 | I14: 1013259 | J14: 3 kasser 6 | K14: 592x592x520 | M14: nej | O14: 45910 | P14: =IF(AND(A14="",B14="",C14=""),"",IF(O14="",-1000,(O14-TODAY()))) -> -127 | Q14: jens/Ian | S14: admin 40 til 43 | W14: Billeder\SVANEN\BLOK B GAMMEL
A16: Sundvænget 9 | B16: Øhavsskolen Svanen | C16: byg b loft | D16: ve05 | H16: 1013638 | I16: 1013638 | J16: 2 | K16: 592x287x370 | M16: nej | O16: 45910 | P16: =IF(AND(A16="",B16="",C16=""),"",IF(O16="",-1000,(O16-TODAY()))) -> -127 | Q16: jens/Ian | S16: admin 40 til 43
A18: Sundvænget 9 | B18: Øhavsskolen Svanen | C18: græs på taget | D18: ve06 | H18: 1013259 | I18: 1013259 | J18: 2 | K18: 592x592x520 | M18: ja | O18: 45910 | P18: =IF(AND(A18="",B18="",C18=""),"",IF(O18="",-1000,(O18-TODAY()))) -> -127 | Q18: per/ jens | W18: Billeder\SVANEN\HUS MED GRÆS PÅ TAG
A19: Sundvænget 9 | B19: Øhavsskolen Svanen | C19: græs på taget | D19: ve06 | H19: 1013498 | I19: 1013498 | J19: 2 | K19: 490x520x520 | M19: ja | O19: 45910 | P19: =IF(AND(A19="",B19="",C19=""),"",IF(O19="",-1000,(O19-TODAY()))) -> -127 | Q19: per / jens
A20: Sundvænget 9 | B20: Øhavsskolen Svanen | C20: græs på taget | D20: ve06 | H20: 1013128 | I20: 1013128 | J20: 2 | K20: 287x592x520 | M20: ja | O20: 45910 | P20: =IF(AND(A20="",B20="",C20=""),"",IF(O20="",-1000,(O20-TODAY()))) -> -127 | Q20: per / jens
A22: Sundvænget 9 | B22: Øhavsskolen Svanen | C22: byg c kælder | D22: ve07 | I22: dk23454402 | J22: 2 | K22: 490x450x48 | M22: nej | O22: 45910 | P22: =IF(AND(A22="",B22="",C22=""),"",IF(O22="",-1000,(O22-TODAY()))) -> -127 | Q22: jens | W22: Billeder\SVANEN\TAG VE 03
P23: =IF(AND(A23="",B23="",C23=""),"",IF(O23="",-1000,(O23-TODAY())))
A24: Sundvænget 9 | B24: Øhavsskolen Svanen | C24: Tårnbygningen | E24: Airmaster | J24: 1 | M24: nej | O24: 45721 | P24: =IF(AND(A24="",B24="",C24=""),"",IF(O24="",-1000,(O24-TODAY()))) -> -316 | Q24: Jens/Kjeld | V24: JA
A25: Sundvænget 9 | B25: Øhavsskolen Svanen | C25: Tårnbygningen | E25: Airmaster | J25: 1 | M25: nej | O25: 45721 | Q25: Jens/Kjeld | V25: JA
P26: =IF(AND(A26="",B26="",C26=""),"",IF(O26="",-1000,(O26-TODAY())))
A27: Sundvænget 9 | B27: Øhavsskolen Svanen | C27: Tårnbygningen | E27: Airmaster | J27: 1 | M27: nej | O27: 45721 | P27: =IF(AND(A27="",B27="",C27=""),"",IF(O27="",-1000,(O27-TODAY()))) -> -316 | Q27: Jens/Kjeld | V27: JA
A28: Sundvænget 9 | B28: Øhavsskolen Svanen | C28: Tårnbygningen | E28: Airmaster | J28: 1 | M28: nej | O28: 45721 | P28: =IF(AND(A28="",B28="",C28=""),"",IF(O28="",-1000,(O28-TODAY()))) -> -316 | Q28: Jens/Kjeld | V28: JA
P29: =IF(AND(A29="",B29="",C29=""),"",IF(O29="",-1000,(O29-TODAY())))
A30: Sundvænget 9 | B30: Øhavsskolen Svanen | C30: Tårnbygningen | E30: Airmaster | J30: 1 | M30: nej | O30: 45721 | P30: =IF(AND(A30="",B30="",C30=""),"",IF(O30="",-1000,(O30-TODAY()))) -> -316 | Q30: Jens/Kjeld | V30: JA
A31: Sundvænget 9 | B31: Øhavsskolen Svanen | C31: Tårnbygningen | E31: Airmaster | J31: 1 | M31: nej | O31: 45721 | P31: =IF(AND(A31="",B31="",C31=""),"",IF(O31="",-1000,(O31-TODAY()))) -> -316 | Q31: Jens/Kjeld | V31: JA
P32: =IF(AND(A32="",B32="",C32=""),"",IF(O32="",-1000,(O32-TODAY())))
P33: =IF(AND(A33="",B33="",C33=""),"",IF(O33="",-1000,(O33-TODAY())))
P34: =IF(AND(A34="",B34="",C34=""),"",IF(O34="",-1000,(O34-TODAY())))
P35: =IF(AND(A35="",B35="",C35=""),"",IF(O35="",-1000,(O35-TODAY())))
P36: =IF(AND(A36="",B36="",C36=""),"",IF(O36="",-1000,(O36-TODAY())))
P37: =IF(AND(A37="",B37="",C37=""),"",IF(O37="",-1000,(O37-TODAY())))
P38: =IF(AND(A38="",B38="",C38=""),"",IF(O38="",-1000,(O38-TODAY())))
P39: =IF(AND(A39="",B39="",C39=""),"",IF(O39="",-1000,(O39-TODAY())))
P40: =IF(AND(A40="",B40="",C40=""),"",IF(O40="",-1000,(O40-TODAY())))
P41: =IF(AND(A41="",B41="",C41=""),"",IF(O41="",-1000,(O41-TODAY())))
P42: =IF(AND(A42="",B42="",C42=""),"",IF(O42="",-1000,(O42-TODAY())))
P43: =IF(AND(A43="",B43="",C43=""),"",IF(O43="",-1000,(O43-TODAY())))
P44: =IF(AND(A44="",B44="",C44=""),"",IF(O44="",-1000,(O44-TODAY())))

Sheet Øhavsskolen Uglen
A1: Adresse | B1: Navn | C1: Placering på anlæg | D1: Anlægsnr. | E1: Leverandør | F1: Type | G1: Årstal for opsætning | H1: Gammel filter nr | I1: Nyt filter nr | J1: Antal filtre | K1: Str på filter | L1: Styring | M1: Frostsikring | N1: Luftmængde (Vent-ordning) | O1: Dato for filterskifte | P1: Dage siden skift | Q1: Person som har skiftet filtret | R1: Dato på eftersyn (VENT-ordning) | S1: Kommentar. / Anmærkninger | T1: Service | U1: Hvornår udløber kontrakt
A2: Toftegårdsvej 7 | B2: Øhavsskolerne afd. Uglen | C2: Bananen | D2: ve 01 | E2: Kemp & Lauritzen | F2: Exhausto VEX3.5-4-1MPR EVR57 | G2: 2011 | H2: 1104785 | I2: 1104785 | J2: 2 | K2: 490x450x48 | L2: CTS | M2: isoleretrum ja | O2: 45890 | P2: =IF(AND(A2="",B2="",C2=""),"",IF(O2="",-1000,(O2-TODAY()))) -> -147 | Q2: Ian/Kjeld | S2: ingen
A3: Toftegårdsvej 7 | B3: Øhavsskolerne afd. Uglen | C3: Bananen | D3: ve 02 | E3: Kemp & Lauritzen | F3: Exhausto VEX3.5-4-1MPR EVR57 | G3: 2011 | H3: 1104785 | I3: 1104785 | J3: 2 | K3: 490x450x48 | L3: CTS | M3: isoleretrum ja | O3: 45890 | P3: =IF(AND(A3="",B3="",C3=""),"",IF(O3="",-1000,(O3-TODAY()))) -> -147 | Q3: Ian/Kjeld | S3: ingen
A4: Toftegårdsvej 7 | B4: Øhavsskolerne afd. Uglen | C4: Bananen | D4: ve 03 | E4: Kemp & Lauritzen | F4: Exhausto VEX3.5-4-1MPR EVR57 | G4: 2011 | H4: 1104785 | I4: 1104785 | J4: 2 | K4: 490x450x48 | L4: CTS | M4: isoleretrum ja | O4: 45890 | P4: =IF(AND(A4="",B4="",C4=""),"",IF(O4="",-1000,(O4-TODAY()))) -> -147 | Q4: Ian/Kjeld | S4: ingen
A5: Toftegårdsvej 7 | B5: Øhavsskolerne afd. Uglen | C5: Bananen | D5: ve 04 | E5: Kemp & Lauritzen | F5: Exhausto VEX3.5-4-1MPR EVR57 | G5: 2011 | H5: 1104785 | I5: 1104785 | J5: 2 | K5: 490x450x48 | L5: CTS | M5: isoleretrum ja | O5: 45890 | P5: =IF(AND(A5="",B5="",C5=""),"",IF(O5="",-1000,(O5-TODAY()))) -> -147 | Q5: Ian/Kjeld | S5: ingen
P6: =IF(AND(A6="",B6="",C6=""),"",IF(O6="",-1000,(O6-TODAY())))
A7: Toftegårdsvej 7 | B7: Øhavsskolerne afd. Uglen | C7: blok 4 | D7: ve 05 | E7: NOVENCO | F7: Climaster ZCF-15 10C-R1 | G7: 2011 | H7: 1013468 små | I7: 1013468 små | J7: 1 | K7: 490x592x520 | L7: CTS | M7: isoleretrum ja | O7: 45889 | P7: =IF(AND(A7="",B7="",C7=""),"",IF(O7="",-1000,(O7-TODAY()))) -> -148 | Q7: Per / Kjeld
A8: Toftegårdsvej 7 | B8: Øhavsskolerne afd. Uglen | C8: blok 4 | D8: ve 05 | E8: NOVENCO | F8: Climaster ZCF-15 10C-R1 | G8: 2011 | H8: 1013247 store | I8: 1013247 store | J8: 1 | K8: 592x592x520 | L8: CTS | M8: isoleretrum ja | O8: 45889 | P8: =IF(AND(A8="",B8="",C8=""),"",IF(O8="",-1000,(O8-TODAY()))) -> -148 | Q8: Per / Kjeld | V8: 2 extra
A9: Toftegårdsvej 7 | B9: Øhavsskolerne afd. Uglen | C9: blok 4 | D9: ve 05 | E9: NOVENCO | F9: Climaster ZCF-15 10C-R1 | G9: 2011 | H9: 1013259 stor | I9: 1013259 stor | J9: 1 | K9: 592x592x520 | L9: CTS | M9: isoleretrum ja | O9: 45889 | P9: =IF(AND(A9="",B9="",C9=""),"",IF(O9="",-1000,(O9-TODAY()))) -> -148 | Q9: Per / Kjeld
A10: Toftegårdsvej 7 | B10: Øhavsskolerne afd. Uglen | C10: blok 4 | D10: ve 05 | E10: NOVENCO | F10: Climaster ZCF-15 10C-R1 | G10: 2011 | H10: 1013498 Ssmå | I10: 1013498 Ssmå | J10: 1 | K10: 490x592x520 | L10: CTS | M10: isoleretrum ja | O10: 45889 | P10: =IF(AND(A10="",B10="",C10=""),"",IF(O10="",-1000,(O10-TODAY()))) -> -148 | Q10: Per / Kjeld
P11: =IF(AND(A11="",B11="",C11=""),"",IF(O11="",-1000,(O11-TODAY())))
A12: Toftegårdsvej 7 | B12: Øhavsskolerne afd. Uglen | C12: blok 5 fagblok | D12: VE01- KØKKEN | E12: Belvent A/S | F12: Geniox 10 | G12: 2024 | I12: 1013898 | J12: 1 | K12: 792 x 392 x 520 | L12: CTS | M12: ja | O12: 45566 | P12: =IF(AND(A12="",B12="",C12=""),"",IF(O12="",-1000,(O12-TODAY()))) -> -471
A13: Toftegårdsvej 7 | B13: Øhavsskolerne afd. Uglen | C13: blok 5 fagblok | D13: VE01- KØKKEN | E13: Belvent A/S | F13: Geniox 10 | G13: 2024 | I13: 1014015 | J13: 1 | K13: 792 x 392 x 640 | L13: CTS | M13: ja | O13: 45566 | P13: =IF(AND(A13="",B13="",C13=""),"",IF(O13="",-1000,(O13-TODAY()))) -> -471
P14: =IF(AND(A14="",B14="",C14=""),"",IF(O14="",-1000,(O14-TODAY())))
A15: Toftegårdsvej 7 | B15: Øhavsskolerne afd. Uglen | C15: blok 5 på taget fagblok | D15: VE02- LOKALER | E15: Belvent A/S | F15: Geniox 14 | G15: 2024 | I15: 1013534 | J15: 3 | K15: 287 X 592 X 520 | L15: CTS | M15: ja | O15: 45566 | P15: =IF(AND(A15="",B15="",C15=""),"",IF(O15="",-1000,(O15-TODAY()))) -> -471
A16: Toftegårdsvej 7 | B16: Øhavsskolerne afd. Uglen | C16: blok 5 på taget fagblok | D16: VE02- LOKALER | E16: Belvent A/S | F16: Geniox 14 | G16: 2024 | I16: 1013181 | J16: 3 | K16: 287 X 592 X640 | L16: CTS | M16: ja | O16: 45566 | P16: =IF(AND(A16="",B16="",C16=""),"",IF(O16="",-1000,(O16-TODAY()))) -> -471
A18: Toftegårdsvej 7 | B18: Øhavsskolerne afd. Uglen | C18: hallen køber selv til den | D18: ve 10 | H18: vi kiipper selv filter til | I18: vi kiipper selv filter til | J18: 2 | K18: 860 x 750 | L18: NEJ | O18: 45803 | P18: =IF(AND(A18="",B18="",C18=""),"",IF(O18="",-1000,(O18-TODAY()))) -> -234 | Q18: Per / Kjeld
A20: Toftegårdsvej 7 | B20: Øhavsskolerne afd. Uglen | C20: Blok 1 på taget | D20: VE11 | E20: JS Ventilation a/s | F20: Geniox Core 18 | G20: 2023 | H20: 308603 /GFP 76460801 | I20: 1013894 / 615796 | J20: 4 | K20: 592 x392 x 520 | L20: CTS | M20: ja | O20: 45796 | P20: =IF(AND(A20="",B20="",C20=""),"",IF(O20="",-1000,(O20-TODAY()))) -> -241 | Q20: Per / Kjeld | V20: Billeder\UGLEN\Uglen blok 1
A21: Toftegårdsvej 7 | B21: Øhavsskolerne afd. Uglen | C21: Blok 1 på taget | D21: VE11 | E21: JS Ventilation a/s | F21: Geniox Core 18 | G21: 2023 | H21: 297307 / MPP 5408 | I21: 1013879 / 615789 | J21: 2 | K21: 490 x392 x 520 | L21: CTS | M21: ja | O21: 45796 | P21: =IF(AND(A21="",B21="",C21=""),"",IF(O21="",-1000,(O21-TODAY()))) -> -241 | Q21: Per / Kjeld
A22: Toftegårdsvej 7 | B22: Øhavsskolerne afd. Uglen | C22: Blok 1 på taget | D22: VE11 | E22: JS Ventilation a/s | F22: Geniox Core 18 | G22: 2023 | H22: 305245 / MPG 56460601 | I22: 1013894 / 615796 | J22: 4 | K22: 592 x392 x 520 | L22: CTS | M22: ja | O22: 45796 | P22: =IF(AND(A22="",B22="",C22=""),"",IF(O22="",-1000,(O22-TODAY()))) -> -241 | Q22: Per / Kjeld
